Workbook

Sheet Dashboard
B2: Neurolumens · Dashboard mensual
B4: Mes seleccionado | C4: =DATE(Configuración!C5,Configuración!C6,1) -> 46023
B6: Indicador | C6: Mes | D6: Año completo
B7: Ingresos por servicios | C7: =INDEX(KPIs!$C$7:$N$7,1,Configuración!$C$6) -> 2200 | D7: =KPIs!O7 -> 2200
B8: Utilidad neta | C8: =INDEX(KPIs!$C$8:$N$8,1,Configuración!$C$6) -> 2200 | D8: =KPIs!O8 -> 2200
B9: Margen neto | C9: =INDEX(KPIs!$C$11:$N$11,1,Configuración!$C$6) -> 1 | D9: =KPIs!O11 -> 1
B10: Flujo operativo | C10: =INDEX(KPIs!$C$14:$N$14,1,Configuración!$C$6) -> 2200 | D10: =KPIs!O14 -> 2200
B11: Efectivo al cierre | C11: =INDEX(KPIs!$C$15:$N$15,1,Configuración!$C$6) -> 2200 | D11: =KPIs!O15 -> 2200
B12: Retiros familiares | C12: =INDEX(KPIs!$C$19:$N$19,1,Configuración!$C$6) -> 0 | D12: =KPIs!O19 -> 0
B13: Remuneraciones familiares pagadas | C13: =INDEX(KPIs!$C$20:$N$20,1,Configuración!$C$6) -> 0 | D13: =KPIs!O20 -> 0
B14: Salida total a la familia | C14: =INDEX(KPIs!$C$21:$N$21,1,Configuración!$C$6) -> 0 | D14: =KPIs!O21 -> 0
B15: Deuda financiera | C15: =INDEX(KPIs!$C$18:$N$18,1,Configuración!$C$6) -> 0 | D15: =KPIs!O18 -> 0
B16: Cuentas por cobrar | C16: =INDEX(KPIs!$C$23:$N$23,1,Configuración!$C$6) -> 0 | D16: =KPIs!O23 -> 0
B18: Empieza en Instrucciones y Configuración. Captura en amarillo; fórmulas en blanco.
B19: Los importes en cero no prueban que el mes esté completo. Revisa Control antes de cerrar.
B23: Mes | C23: Ingresos | D23: Utilidad neta | E23: Efectivo final | F23: Retiros familiares
B24: Ene | C24: ='Estado de Resultados'!C14 -> 2200 | D24: ='Estado de Resultados'!C33 -> 2200 | E24: ='Flujo de Efectivo'!C25 -> 2200 | F24: ='Flujo de Efectivo'!C20 -> 0
B25: Feb | C25: ='Estado de Resultados'!D14 -> 0 | D25: ='Estado de Resultados'!D33 -> 0 | E25: ='Flujo de Efectivo'!D25 -> 2200 | F25: ='Flujo de Efectivo'!D20 -> 0
B26: Mar | C26: ='Estado de Resultados'!E14 -> 0 | D26: ='Estado de Resultados'!E33 -> 0 | E26: ='Flujo de Efectivo'!E25 -> 2200 | F26: ='Flujo de Efectivo'!E20 -> 0
B27: Abr | C27: ='Estado de Resultados'!F14 -> 0 | D27: ='Estado de Resultados'!F33 -> 0 | E27: ='Flujo de Efectivo'!F25 -> 2200 | F27: ='Flujo de Efectivo'!F20 -> 0
B28: May | C28: ='Estado de Resultados'!G14 -> 0 | D28: ='Estado de Resultados'!G33 -> 0 | E28: ='Flujo de Efectivo'!G25 -> 2200 | F28: ='Flujo de Efectivo'!G20 -> 0
B29: Jun | C29: ='Estado de Resultados'!H14 -> 0 | D29: ='Estado de Resultados'!H33 -> 0 | E29: ='Flujo de Efectivo'!H25 -> 2200 | F29: ='Flujo de Efectivo'!H20 -> 0
B30: Jul | C30: ='Estado de Resultados'!I14 -> 0 | D30: ='Estado de Resultados'!I33 -> 0 | E30: ='Flujo de Efectivo'!I25 -> 2200 | F30: ='Flujo de Efectivo'!I20 -> 0
B31: Ago | C31: ='Estado de Resultados'!J14 -> 0 | D31: ='Estado de Resultados'!J33 -> 0 | E31: ='Flujo de Efectivo'!J25 -> 2200 | F31: ='Flujo de Efectivo'!J20 -> 0
B32: Sep | C32: ='Estado de Resultados'!K14 -> 0 | D32: ='Estado de Resultados'!K33 -> 0 | E32: ='Flujo de Efectivo'!K25 -> 2200 | F32: ='Flujo de Efectivo'!K20 -> 0
B33: Oct | C33: ='Estado de Resultados'!L14 -> 0 | D33: ='Estado de Resultados'!L33 -> 0 | E33: ='Flujo de Efectivo'!L25 -> 2200 | F33: ='Flujo de Efectivo'!L20 -> 0
B34: Nov | C34: ='Estado de Resultados'!M14 -> 0 | D34: ='Estado de Resultados'!M33 -> 0 | E34: ='Flujo de Efectivo'!M25 -> 2200 | F34: ='Flujo de Efectivo'!M20 -> 0
B35: Dic | C35: ='Estado de Resultados'!N14 -> 0 | D35: ='Estado de Resultados'!N33 -> 0 | E35: ='Flujo de Efectivo'!N25 -> 2200 | F35: ='Flujo de Efectivo'!N20 -> 0

Sheet Configuración
B2: Configuración
B5: Año de captura | C5: 2026
B6: Mes del dashboard (1–12) | C6: 1
B8: Saldos al 31 de diciembre anterior
B9: Efectivo y bancos iniciales | C9: 0 | E9: Activos iniciales: captúralos en Activos con fecha de compra anterior al año.
B10: Cuentas por cobrar iniciales | C10: 0
B11: IVA recuperable inicial | C11: 0 | E11: Deudas iniciales: usa Saldo inicial en Pasivos, con fecha 31/12 del año anterior.
B12: Retenciones ISR a favor iniciales | C12: 0
B13: Retenciones IVA a favor iniciales | C13: 0 | E13: Capital y resultados: captura saldos reales. No se calculan para forzar el balance.
B14: Cuentas por pagar iniciales | C14: 0
B15: Anticipos de pacientes iniciales | C15: 0 | E15: Un archivo por año. Para un año nuevo, usa una copia y traslada los saldos de cierre.
B16: IVA por pagar inicial | C16: 0
B17: ISR por pagar inicial | C17: 0 | E17: Ceros iniciales son campos por completar; no son cifras reales de Neurolumens.
B18: Capital / aportaciones iniciales | C18: 0
B19: Resultados acumulados iniciales | C19: 0

Sheet Estado de Resultados
B2: Estado de Resultados
B4: MXN · enero a diciembre
B6: Concepto | C6: =DATE(Configuración!$C$5,1,1) -> 46023 | D6: =DATE(Configuración!$C$5,2,1) -> 46054 | E6: =DATE(Configuración!$C$5,3,1) -> 46082 | F6: =DATE(Configuración!$C$5,4,1) -> 46113 | G6: =DATE(Configuración!$C$5,5,1) -> 46143 | H6: =DATE(Configuración!$C$5,6,1) -> 46174 | I6: =DATE(Configuración!$C$5,7,1) -> 46204 | J6: =DATE(Configuración!$C$5,8,1) -> 46235 | K6: =DATE(Configuración!$C$5,9,1) -> 46266 | L6: =DATE(Configuración!$C$5,10,1) -> 46296 | M6: =DATE(Configuración!$C$5,11,1) -> 46327 | N6: =DATE(Configuración!$C$5,12,1) -> 46357 | O6: Total anual
B7: TMS | C7: =SUMIFS(Ingresos!$G$7:$G$2006,Ingresos!$B$7:$B$2006,">="&C$6,Ingresos!$B$7:$B$2006,"<"&EDATE(C$6,1),Ingresos!$C$7:$C$2006,"Servicio",Ingresos!$F$7:$F$2006,"TMS") -> 2200 | D7: =SUMIFS(Ingresos!$G$7:$G$2006,Ingresos!$B$7:$B$2006,">="&D$6,Ingresos!$B$7:$B$2006,"<"&EDATE(D$6,1),Ingresos!$C$7:$C$2006,"Servicio",Ingresos!$F$7:$F$2006,"TMS") -> 0 | E7: =SUMIFS(Ingresos!$G$7:$G$2006,Ingresos!$B$7:$B$2006,">="&E$6,Ingresos!$B$7:$B$2006,"<"&EDATE(E$6,1),Ingresos!$C$7:$C$2006,"Servicio",Ingresos!$F$7:$F$2006,"TMS") -> 0 | F7: =SUMIFS(Ingresos!$G$7:$G$2006,Ingresos!$B$7:$B$2006,">="&F$6,Ingresos!$B$7:$B$2006,"<"&EDATE(F$6,1),Ingresos!$C$7:$C$2006,"Servicio",Ingresos!$F$7:$F$2006,"TMS") -> 0 | G7: =SUMIFS(Ingresos!$G$7:$G$2006,Ingresos!$B$7:$B$2006,">="&G$6,Ingresos!$B$7:$B$2006,"<"&EDATE(G$6,1),Ingresos!$C$7:$C$2006,"Servicio",Ingresos!$F$7:$F$2006,"TMS") -> 0 | H7: =SUMIFS(Ingresos!$G$7:$G$2006,Ingresos!$B$7:$B$2006,">="&H$6,Ingresos!$B$7:$B$2006,"<"&EDATE(H$6,1),Ingresos!$C$7:$C$2006,"Servicio",Ingresos!$F$7:$F$2006,"TMS") -> 0 | I7: =SUMIFS(Ingresos!$G$7:$G$2006,Ingresos!$B$7:$B$2006,">="&I$6,Ingresos!$B$7:$B$2006,"<"&EDATE(I$6,1),Ingresos!$C$7:$C$2006,"Servicio",Ingresos!$F$7:$F$2006,"TMS") -> 0 | J7: =SUMIFS(Ingresos!$G$7:$G$2006,Ingresos!$B$7:$B$2006,">="&J$6,Ingresos!$B$7:$B$2006,"<"&EDATE(J$6,1),Ingresos!$C$7:$C$2006,"Servicio",Ingresos!$F$7:$F$2006,"TMS") -> 0 | ... N7: =SUMIFS(Ingresos!$G$7:$G$2006,Ingresos!$B$7:$B$2006,">="&N$6,Ingresos!$B$7:$B$2006,"<"&EDATE(N$6,1),Ingresos!$C$7:$C$2006,"Servicio",Ingresos!$F$7:$F$2006,"TMS") -> 0 | O7: =SUM(C7:N7) -> 2200
B8: Valoración | C8: =SUMIFS(Ingresos!$G$7:$G$2006,Ingresos!$B$7:$B$2006,">="&C$6,Ingresos!$B$7:$B$2006,"<"&EDATE(C$6,1),Ingresos!$C$7:$C$2006,"Servicio",Ingresos!$F$7:$F$2006,"Valoración") -> 0 | D8: =SUMIFS(Ingresos!$G$7:$G$2006,Ingresos!$B$7:$B$2006,">="&D$6,Ingresos!$B$7:$B$2006,"<"&EDATE(D$6,1),Ingresos!$C$7:$C$2006,"Servicio",Ingresos!$F$7:$F$2006,"Valoración") -> 0 | E8: =SUMIFS(Ingresos!$G$7:$G$2006,Ingresos!$B$7:$B$2006,">="&E$6,Ingresos!$B$7:$B$2006,"<"&EDATE(E$6,1),Ingresos!$C$7:$C$2006,"Servicio",Ingresos!$F$7:$F$2006,"Valoración") -> 0 | F8: =SUMIFS(Ingresos!$G$7:$G$2006,Ingresos!$B$7:$B$2006,">="&F$6,Ingresos!$B$7:$B$2006,"<"&EDATE(F$6,1),Ingresos!$C$7:$C$2006,"Servicio",Ingresos!$F$7:$F$2006,"Valoración") -> 0 | G8: =SUMIFS(Ingresos!$G$7:$G$2006,Ingresos!$B$7:$B$2006,">="&G$6,Ingresos!$B$7:$B$2006,"<"&EDATE(G$6,1),Ingresos!$C$7:$C$2006,"Servicio",Ingresos!$F$7:$F$2006,"Valoración") -> 0 | H8: =SUMIFS(Ingresos!$G$7:$G$2006,Ingresos!$B$7:$B$2006,">="&H$6,Ingresos!$B$7:$B$2006,"<"&EDATE(H$6,1),Ingresos!$C$7:$C$2006,"Servicio",Ingresos!$F$7:$F$2006,"Valoración") -> 0 | I8: =SUMIFS(Ingresos!$G$7:$G$2006,Ingresos!$B$7:$B$2006,">="&I$6,Ingresos!$B$7:$B$2006,"<"&EDATE(I$6,1),Ingresos!$C$7:$C$2006,"Servicio",Ingresos!$F$7:$F$2006,"Valoración") -> 0 | J8: =SUMIFS(Ingresos!$G$7:$G$2006,Ingresos!$B$7:$B$2006,">="&J$6,Ingresos!$B$7:$B$2006,"<"&EDATE(J$6,1),Ingresos!$C$7:$C$2006,"Servicio",Ingresos!$F$7:$F$2006,"Valoración") -> 0 | ... N8: =SUMIFS(Ingresos!$G$7:$G$2006,Ingresos!$B$7:$B$2006,">="&N$6,Ingresos!$B$7:$B$2006,"<"&EDATE(N$6,1),Ingresos!$C$7:$C$2006,"Servicio",Ingresos!$F$7:$F$2006,"Valoración") -> 0 | O8: =SUM(C8:N8) -> 0
B9: EEG | C9: =SUMIFS(Ingresos!$G$7:$G$2006,Ingresos!$B$7:$B$2006,">="&C$6,Ingresos!$B$7:$B$2006,"<"&EDATE(C$6,1),Ingresos!$C$7:$C$2006,"Servicio",Ingresos!$F$7:$F$2006,"EEG") -> 0 | D9: =SUMIFS(Ingresos!$G$7:$G$2006,Ingresos!$B$7:$B$2006,">="&D$6,Ingresos!$B$7:$B$2006,"<"&EDATE(D$6,1),Ingresos!$C$7:$C$2006,"Servicio",Ingresos!$F$7:$F$2006,"EEG") -> 0 | E9: =SUMIFS(Ingresos!$G$7:$G$2006,Ingresos!$B$7:$B$2006,">="&E$6,Ingresos!$B$7:$B$2006,"<"&EDATE(E$6,1),Ingresos!$C$7:$C$2006,"Servicio",Ingresos!$F$7:$F$2006,"EEG") -> 0 | F9: =SUMIFS(Ingresos!$G$7:$G$2006,Ingresos!$B$7:$B$2006,">="&F$6,Ingresos!$B$7:$B$2006,"<"&EDATE(F$6,1),Ingresos!$C$7:$C$2006,"Servicio",Ingresos!$F$7:$F$2006,"EEG") -> 0 | G9: =SUMIFS(Ingresos!$G$7:$G$2006,Ingresos!$B$7:$B$2006,">="&G$6,Ingresos!$B$7:$B$2006,"<"&EDATE(G$6,1),Ingresos!$C$7:$C$2006,"Servicio",Ingresos!$F$7:$F$2006,"EEG") -> 0 | H9: =SUMIFS(Ingresos!$G$7:$G$2006,Ingresos!$B$7:$B$2006,">="&H$6,Ingresos!$B$7:$B$2006,"<"&EDATE(H$6,1),Ingresos!$C$7:$C$2006,"Servicio",Ingresos!$F$7:$F$2006,"EEG") -> 0 | I9: =SUMIFS(Ingresos!$G$7:$G$2006,Ingresos!$B$7:$B$2006,">="&I$6,Ingresos!$B$7:$B$2006,"<"&EDATE(I$6,1),Ingresos!$C$7:$C$2006,"Servicio",Ingresos!$F$7:$F$2006,"EEG") -> 0 | J9: =SUMIFS(Ingresos!$G$7:$G$2006,Ingresos!$B$7:$B$2006,">="&J$6,Ingresos!$B$7:$B$2006,"<"&EDATE(J$6,1),Ingresos!$C$7:$C$2006,"Servicio",Ingresos!$F$7:$F$2006,"EEG") -> 0 | ... N9: =SUMIFS(Ingresos!$G$7:$G$2006,Ingresos!$B$7:$B$2006,">="&N$6,Ingresos!$B$7:$B$2006,"<"&EDATE(N$6,1),Ingresos!$C$7:$C$2006,"Servicio",Ingresos!$F$7:$F$2006,"EEG") -> 0 | O9: =SUM(C9:N9) -> 0
B10: Neurofeedback | C10: =SUMIFS(Ingresos!$G$7:$G$2006,Ingresos!$B$7:$B$2006,">="&C$6,Ingresos!$B$7:$B$2006,"<"&EDATE(C$6,1),Ingresos!$C$7:$C$2006,"Servicio",Ingresos!$F$7:$F$2006,"Neurofeedback") -> 0 | D10: =SUMIFS(Ingresos!$G$7:$G$2006,Ingresos!$B$7:$B$2006,">="&D$6,Ingresos!$B$7:$B$2006,"<"&EDATE(D$6,1),Ingresos!$C$7:$C$2006,"Servicio",Ingresos!$F$7:$F$2006,"Neurofeedback") -> 0 | E10: =SUMIFS(Ingresos!$G$7:$G$2006,Ingresos!$B$7:$B$2006,">="&E$6,Ingresos!$B$7:$B$2006,"<"&EDATE(E$6,1),Ingresos!$C$7:$C$2006,"Servicio",Ingresos!$F$7:$F$2006,"Neurofeedback") -> 0 | F10: =SUMIFS(Ingresos!$G$7:$G$2006,Ingresos!$B$7:$B$2006,">="&F$6,Ingresos!$B$7:$B$2006,"<"&EDATE(F$6,1),Ingresos!$C$7:$C$2006,"Servicio",Ingresos!$F$7:$F$2006,"Neurofeedback") -> 0 | G10: =SUMIFS(Ingresos!$G$7:$G$2006,Ingresos!$B$7:$B$2006,">="&G$6,Ingresos!$B$7:$B$2006,"<"&EDATE(G$6,1),Ingresos!$C$7:$C$2006,"Servicio",Ingresos!$F$7:$F$2006,"Neurofeedback") -> 0 | H10: =SUMIFS(Ingresos!$G$7:$G$2006,Ingresos!$B$7:$B$2006,">="&H$6,Ingresos!$B$7:$B$2006,"<"&EDATE(H$6,1),Ingresos!$C$7:$C$2006,"Servicio",Ingresos!$F$7:$F$2006,"Neurofeedback") -> 0 | I10: =SUMIFS(Ingresos!$G$7:$G$2006,Ingresos!$B$7:$B$2006,">="&I$6,Ingresos!$B$7:$B$2006,"<"&EDATE(I$6,1),Ingresos!$C$7:$C$2006,"Servicio",Ingresos!$F$7:$F$2006,"Neurofeedback") -> 0 | J10: =SUMIFS(Ingresos!$G$7:$G$2006,Ingresos!$B$7:$B$2006,">="&J$6,Ingresos!$B$7:$B$2006,"<"&EDATE(J$6,1),Ingresos!$C$7:$C$2006,"Servicio",Ingresos!$F$7:$F$2006,"Neurofeedback") -> 0 | ... N10: =SUMIFS(Ingresos!$G$7:$G$2006,Ingresos!$B$7:$B$2006,">="&N$6,Ingresos!$B$7:$B$2006,"<"&EDATE(N$6,1),Ingresos!$C$7:$C$2006,"Servicio",Ingresos!$F$7:$F$2006,"Neurofeedback") -> 0 | O10: =SUM(C10:N10) -> 0
B11: Fotobiomodulación | C11: =SUMIFS(Ingresos!$G$7:$G$2006,Ingresos!$B$7:$B$2006,">="&C$6,Ingresos!$B$7:$B$2006,"<"&EDATE(C$6,1),Ingresos!$C$7:$C$2006,"Servicio",Ingresos!$F$7:$F$2006,"Fotobiomodulación") -> 0 | D11: =SUMIFS(Ingresos!$G$7:$G$2006,Ingresos!$B$7:$B$2006,">="&D$6,Ingresos!$B$7:$B$2006,"<"&EDATE(D$6,1),Ingresos!$C$7:$C$2006,"Servicio",Ingresos!$F$7:$F$2006,"Fotobiomodulación") -> 0 | E11: =SUMIFS(Ingresos!$G$7:$G$2006,Ingresos!$B$7:$B$2006,">="&E$6,Ingresos!$B$7:$B$2006,"<"&EDATE(E$6,1),Ingresos!$C$7:$C$2006,"Servicio",Ingresos!$F$7:$F$2006,"Fotobiomodulación") -> 0 | F11: =SUMIFS(Ingresos!$G$7:$G$2006,Ingresos!$B$7:$B$2006,">="&F$6,Ingresos!$B$7:$B$2006,"<"&EDATE(F$6,1),Ingresos!$C$7:$C$2006,"Servicio",Ingresos!$F$7:$F$2006,"Fotobiomodulación") -> 0 | G11: =SUMIFS(Ingresos!$G$7:$G$2006,Ingresos!$B$7:$B$2006,">="&G$6,Ingresos!$B$7:$B$2006,"<"&EDATE(G$6,1),Ingresos!$C$7:$C$2006,"Servicio",Ingresos!$F$7:$F$2006,"Fotobiomodulación") -> 0 | H11: =SUMIFS(Ingresos!$G$7:$G$2006,Ingresos!$B$7:$B$2006,">="&H$6,Ingresos!$B$7:$B$2006,"<"&EDATE(H$6,1),Ingresos!$C$7:$C$2006,"Servicio",Ingresos!$F$7:$F$2006,"Fotobiomodulación") -> 0 | I11: =SUMIFS(Ingresos!$G$7:$G$2006,Ingresos!$B$7:$B$2006,">="&I$6,Ingresos!$B$7:$B$2006,"<"&EDATE(I$6,1),Ingresos!$C$7:$C$2006,"Servicio",Ingresos!$F$7:$F$2006,"Fotobiomodulación") -> 0 | J11: =SUMIFS(Ingresos!$G$7:$G$2006,Ingresos!$B$7:$B$2006,">="&J$6,Ingresos!$B$7:$B$2006,"<"&EDATE(J$6,1),Ingresos!$C$7:$C$2006,"Servicio",Ingresos!$F$7:$F$2006,"Fotobiomodulación") -> 0 | ... N11: =SUMIFS(Ingresos!$G$7:$G$2006,Ingresos!$B$7:$B$2006,">="&N$6,Ingresos!$B$7:$B$2006,"<"&EDATE(N$6,1),Ingresos!$C$7:$C$2006,"Servicio",Ingresos!$F$7:$F$2006,"Fotobiomodulación") -> 0 | O11: =SUM(C11:N11) -> 0
B12: Psicoterapia | C12: =SUMIFS(Ingresos!$G$7:$G$2006,Ingresos!$B$7:$B$2006,">="&C$6,Ingresos!$B$7:$B$2006,"<"&EDATE(C$6,1),Ingresos!$C$7:$C$2006,"Servicio",Ingresos!$F$7:$F$2006,"Psicoterapia") -> 0 | D12: =SUMIFS(Ingresos!$G$7:$G$2006,Ingresos!$B$7:$B$2006,">="&D$6,Ingresos!$B$7:$B$2006,"<"&EDATE(D$6,1),Ingresos!$C$7:$C$2006,"Servicio",Ingresos!$F$7:$F$2006,"Psicoterapia") -> 0 | E12: =SUMIFS(Ingresos!$G$7:$G$2006,Ingresos!$B$7:$B$2006,">="&E$6,Ingresos!$B$7:$B$2006,"<"&EDATE(E$6,1),Ingresos!$C$7:$C$2006,"Servicio",Ingresos!$F$7:$F$2006,"Psicoterapia") -> 0 | F12: =SUMIFS(Ingresos!$G$7:$G$2006,Ingresos!$B$7:$B$2006,">="&F$6,Ingresos!$B$7:$B$2006,"<"&EDATE(F$6,1),Ingresos!$C$7:$C$2006,"Servicio",Ingresos!$F$7:$F$2006,"Psicoterapia") -> 0 | G12: =SUMIFS(Ingresos!$G$7:$G$2006,Ingresos!$B$7:$B$2006,">="&G$6,Ingresos!$B$7:$B$2006,"<"&EDATE(G$6,1),Ingresos!$C$7:$C$2006,"Servicio",Ingresos!$F$7:$F$2006,"Psicoterapia") -> 0 | H12: =SUMIFS(Ingresos!$G$7:$G$2006,Ingresos!$B$7:$B$2006,">="&H$6,Ingresos!$B$7:$B$2006,"<"&EDATE(H$6,1),Ingresos!$C$7:$C$2006,"Servicio",Ingresos!$F$7:$F$2006,"Psicoterapia") -> 0 | I12: =SUMIFS(Ingresos!$G$7:$G$2006,Ingresos!$B$7:$B$2006,">="&I$6,Ingresos!$B$7:$B$2006,"<"&EDATE(I$6,1),Ingresos!$C$7:$C$2006,"Servicio",Ingresos!$F$7:$F$2006,"Psicoterapia") -> 0 | J12: =SUMIFS(Ingresos!$G$7:$G$2006,Ingresos!$B$7:$B$2006,">="&J$6,Ingresos!$B$7:$B$2006,"<"&EDATE(J$6,1),Ingresos!$C$7:$C$2006,"Servicio",Ingresos!$F$7:$F$2006,"Psicoterapia") -> 0 | ... N12: =SUMIFS(Ingresos!$G$7:$G$2006,Ingresos!$B$7:$B$2006,">="&N$6,Ingresos!$B$7:$B$2006,"<"&EDATE(N$6,1),Ingresos!$C$7:$C$2006,"Servicio",Ingresos!$F$7:$F$2006,"Psicoterapia") -> 0 | O12: =SUM(C12:N12) -> 0
B13: Otros | C13: =SUMIFS(Ingresos!$G$7:$G$2006,Ingresos!$B$7:$B$2006,">="&C$6,Ingresos!$B$7:$B$2006,"<"&EDATE(C$6,1),Ingresos!$C$7:$C$2006,"Servicio",Ingresos!$F$7:$F$2006,"Otros") -> 0 | D13: =SUMIFS(Ingresos!$G$7:$G$2006,Ingresos!$B$7:$B$2006,">="&D$6,Ingresos!$B$7:$B$2006,"<"&EDATE(D$6,1),Ingresos!$C$7:$C$2006,"Servicio",Ingresos!$F$7:$F$2006,"Otros") -> 0 | E13: =SUMIFS(Ingresos!$G$7:$G$2006,Ingresos!$B$7:$B$2006,">="&E$6,Ingresos!$B$7:$B$2006,"<"&EDATE(E$6,1),Ingresos!$C$7:$C$2006,"Servicio",Ingresos!$F$7:$F$2006,"Otros") -> 0 | F13: =SUMIFS(Ingresos!$G$7:$G$2006,Ingresos!$B$7:$B$2006,">="&F$6,Ingresos!$B$7:$B$2006,"<"&EDATE(F$6,1),Ingresos!$C$7:$C$2006,"Servicio",Ingresos!$F$7:$F$2006,"Otros") -> 0 | G13: =SUMIFS(Ingresos!$G$7:$G$2006,Ingresos!$B$7:$B$2006,">="&G$6,Ingresos!$B$7:$B$2006,"<"&EDATE(G$6,1),Ingresos!$C$7:$C$2006,"Servicio",Ingresos!$F$7:$F$2006,"Otros") -> 0 | H13: =SUMIFS(Ingresos!$G$7:$G$2006,Ingresos!$B$7:$B$2006,">="&H$6,Ingresos!$B$7:$B$2006,"<"&EDATE(H$6,1),Ingresos!$C$7:$C$2006,"Servicio",Ingresos!$F$7:$F$2006,"Otros") -> 0 | I13: =SUMIFS(Ingresos!$G$7:$G$2006,Ingresos!$B$7:$B$2006,">="&I$6,Ingresos!$B$7:$B$2006,"<"&EDATE(I$6,1),Ingresos!$C$7:$C$2006,"Servicio",Ingresos!$F$7:$F$2006,"Otros") -> 0 | J13: =SUMIFS(Ingresos!$G$7:$G$2006,Ingresos!$B$7:$B$2006,">="&J$6,Ingresos!$B$7:$B$2006,"<"&EDATE(J$6,1),Ingresos!$C$7:$C$2006,"Servicio",Ingresos!$F$7:$F$2006,"Otros") -> 0 | ... N13: =SUMIFS(Ingresos!$G$7:$G$2006,Ingresos!$B$7:$B$2006,">="&N$6,Ingresos!$B$7:$B$2006,"<"&EDATE(N$6,1),Ingresos!$C$7:$C$2006,"Servicio",Ingresos!$F$7:$F$2006,"Otros") -> 0 | O13: =SUM(C13:N13) -> 0
B14: Ingresos por servicios | C14: =SUM(C7:C13) -> 2200 | D14: =SUM(D7:D13) -> 0 | E14: =SUM(E7:E13) -> 0 | F14: =SUM(F7:F13) -> 0 | G14: =SUM(G7:G13) -> 0 | H14: =SUM(H7:H13) -> 0 | I14: =SUM(I7:I13) -> 0 | J14: =SUM(J7:J13) -> 0 | ... N14: =SUM(N7:N13) -> 0 | O14: =SUM(C14:N14) -> 2200
B16: Costos clínicos | C16: =SUMIFS(Gastos!$H$7:$H$2006,Gastos!$B$7:$B$2006,">="&C$6,Gastos!$B$7:$B$2006,"<"&EDATE(C$6,1),Gastos!$C$7:$C$2006,"Gasto",Gastos!$D$7:$D$2006,"Costos clínicos") -> 0 | D16: =SUMIFS(Gastos!$H$7:$H$2006,Gastos!$B$7:$B$2006,">="&D$6,Gastos!$B$7:$B$2006,"<"&EDATE(D$6,1),Gastos!$C$7:$C$2006,"Gasto",Gastos!$D$7:$D$2006,"Costos clínicos") -> 0 | E16: =SUMIFS(Gastos!$H$7:$H$2006,Gastos!$B$7:$B$2006,">="&E$6,Gastos!$B$7:$B$2006,"<"&EDATE(E$6,1),Gastos!$C$7:$C$2006,"Gasto",Gastos!$D$7:$D$2006,"Costos clínicos") -> 0 | F16: =SUMIFS(Gastos!$H$7:$H$2006,Gastos!$B$7:$B$2006,">="&F$6,Gastos!$B$7:$B$2006,"<"&EDATE(F$6,1),Gastos!$C$7:$C$2006,"Gasto",Gastos!$D$7:$D$2006,"Costos clínicos") -> 0 | G16: =SUMIFS(Gastos!$H$7:$H$2006,Gastos!$B$7:$B$2006,">="&G$6,Gastos!$B$7:$B$2006,"<"&EDATE(G$6,1),Gastos!$C$7:$C$2006,"Gasto",Gastos!$D$7:$D$2006,"Costos clínicos") -> 0 | H16: =SUMIFS(Gastos!$H$7:$H$2006,Gastos!$B$7:$B$2006,">="&H$6,Gastos!$B$7:$B$2006,"<"&EDATE(H$6,1),Gastos!$C$7:$C$2006,"Gasto",Gastos!$D$7:$D$2006,"Costos clínicos") -> 0 | I16: =SUMIFS(Gastos!$H$7:$H$2006,Gastos!$B$7:$B$2006,">="&I$6,Gastos!$B$7:$B$2006,"<"&EDATE(I$6,1),Gastos!$C$7:$C$2006,"Gasto",Gastos!$D$7:$D$2006,"Costos clínicos") -> 0 | J16: =SUMIFS(Gastos!$H$7:$H$2006,Gastos!$B$7:$B$2006,">="&J$6,Gastos!$B$7:$B$2006,"<"&EDATE(J$6,1),Gastos!$C$7:$C$2006,"Gasto",Gastos!$D$7:$D$2006,"Costos clínicos") -> 0 | ... N16: =SUMIFS(Gastos!$H$7:$H$2006,Gastos!$B$7:$B$2006,">="&N$6,Gastos!$B$7:$B$2006,"<"&EDATE(N$6,1),Gastos!$C$7:$C$2006,"Gasto",Gastos!$D$7:$D$2006,"Costos clínicos") -> 0 | O16: =SUM(C16:N16) -> 0
B17: Utilidad bruta | C17: =C14-C16 -> 2200 | D17: =D14-D16 -> 0 | E17: =E14-E16 -> 0 | F17: =F14-F16 -> 0 | G17: =G14-G16 -> 0 | H17: =H14-H16 -> 0 | I17: =I14-I16 -> 0 | J17: =J14-J16 -> 0 | ... N17: =N14-N16 -> 0 | O17: =SUM(C17:N17) -> 2200
B19: Remuneración familiar por trabajo | C19: =SUMIFS(Gastos!$H$7:$H$2006,Gastos!$B$7:$B$2006,">="&C$6,Gastos!$B$7:$B$2006,"<"&EDATE(C$6,1),Gastos!$C$7:$C$2006,"Gasto",Gastos!$D$7:$D$2006,"Remuneración familiar") -> 0 | D19: =SUMIFS(Gastos!$H$7:$H$2006,Gastos!$B$7:$B$2006,">="&D$6,Gastos!$B$7:$B$2006,"<"&EDATE(D$6,1),Gastos!$C$7:$C$2006,"Gasto",Gastos!$D$7:$D$2006,"Remuneración familiar") -> 0 | E19: =SUMIFS(Gastos!$H$7:$H$2006,Gastos!$B$7:$B$2006,">="&E$6,Gastos!$B$7:$B$2006,"<"&EDATE(E$6,1),Gastos!$C$7:$C$2006,"Gasto",Gastos!$D$7:$D$2006,"Remuneración familiar") -> 0 | F19: =SUMIFS(Gastos!$H$7:$H$2006,Gastos!$B$7:$B$2006,">="&F$6,Gastos!$B$7:$B$2006,"<"&EDATE(F$6,1),Gastos!$C$7:$C$2006,"Gasto",Gastos!$D$7:$D$2006,"Remuneración familiar") -> 0 | G19: =SUMIFS(Gastos!$H$7:$H$2006,Gastos!$B$7:$B$2006,">="&G$6,Gastos!$B$7:$B$2006,"<"&EDATE(G$6,1),Gastos!$C$7:$C$2006,"Gasto",Gastos!$D$7:$D$2006,"Remuneración familiar") -> 0 | H19: =SUMIFS(Gastos!$H$7:$H$2006,Gastos!$B$7:$B$2006,">="&H$6,Gastos!$B$7:$B$2006,"<"&EDATE(H$6,1),Gastos!$C$7:$C$2006,"Gasto",Gastos!$D$7:$D$2006,"Remuneración familiar") -> 0 | I19: =SUMIFS(Gastos!$H$7:$H$2006,Gastos!$B$7:$B$2006,">="&I$6,Gastos!$B$7:$B$2006,"<"&EDATE(I$6,1),Gastos!$C$7:$C$2006,"Gasto",Gastos!$D$7:$D$2006,"Remuneración familiar") -> 0 | J19: =SUMIFS(Gastos!$H$7:$H$2006,Gastos!$B$7:$B$2006,">="&J$6,Gastos!$B$7:$B$2006,"<"&EDATE(J$6,1),Gastos!$C$7:$C$2006,"Gasto",Gastos!$D$7:$D$2006,"Remuneración familiar") -> 0 | ... N19: =SUMIFS(Gastos!$H$7:$H$2006,Gastos!$B$7:$B$2006,">="&N$6,Gastos!$B$7:$B$2006,"<"&EDATE(N$6,1),Gastos!$C$7:$C$2006,"Gasto",Gastos!$D$7:$D$2006,"Remuneración familiar") -> 0 | O19: =SUM(C19:N19) -> 0
B20: Nómina y honorarios | C20: =SUMIFS(Gastos!$H$7:$H$2006,Gastos!$B$7:$B$2006,">="&C$6,Gastos!$B$7:$B$2006,"<"&EDATE(C$6,1),Gastos!$C$7:$C$2006,"Gasto",Gastos!$D$7:$D$2006,"Nómina y honorarios") -> 0 | D20: =SUMIFS(Gastos!$H$7:$H$2006,Gastos!$B$7:$B$2006,">="&D$6,Gastos!$B$7:$B$2006,"<"&EDATE(D$6,1),Gastos!$C$7:$C$2006,"Gasto",Gastos!$D$7:$D$2006,"Nómina y honorarios") -> 0 | E20: =SUMIFS(Gastos!$H$7:$H$2006,Gastos!$B$7:$B$2006,">="&E$6,Gastos!$B$7:$B$2006,"<"&EDATE(E$6,1),Gastos!$C$7:$C$2006,"Gasto",Gastos!$D$7:$D$2006,"Nómina y honorarios") -> 0 | F20: =SUMIFS(Gastos!$H$7:$H$2006,Gastos!$B$7:$B$2006,">="&F$6,Gastos!$B$7:$B$2006,"<"&EDATE(F$6,1),Gastos!$C$7:$C$2006,"Gasto",Gastos!$D$7:$D$2006,"Nómina y honorarios") -> 0 | G20: =SUMIFS(Gastos!$H$7:$H$2006,Gastos!$B$7:$B$2006,">="&G$6,Gastos!$B$7:$B$2006,"<"&EDATE(G$6,1),Gastos!$C$7:$C$2006,"Gasto",Gastos!$D$7:$D$2006,"Nómina y honorarios") -> 0 | H20: =SUMIFS(Gastos!$H$7:$H$2006,Gastos!$B$7:$B$2006,">="&H$6,Gastos!$B$7:$B$2006,"<"&EDATE(H$6,1),Gastos!$C$7:$C$2006,"Gasto",Gastos!$D$7:$D$2006,"Nómina y honorarios") -> 0 | I20: =SUMIFS(Gastos!$H$7:$H$2006,Gastos!$B$7:$B$2006,">="&I$6,Gastos!$B$7:$B$2006,"<"&EDATE(I$6,1),Gastos!$C$7:$C$2006,"Gasto",Gastos!$D$7:$D$2006,"Nómina y honorarios") -> 0 | J20: =SUMIFS(Gastos!$H$7:$H$2006,Gastos!$B$7:$B$2006,">="&J$6,Gastos!$B$7:$B$2006,"<"&EDATE(J$6,1),Gastos!$C$7:$C$2006,"Gasto",Gastos!$D$7:$D$2006,"Nómina y honorarios") -> 0 | ... N20: =SUMIFS(Gastos!$H$7:$H$2006,Gastos!$B$7:$B$2006,">="&N$6,Gastos!$B$7:$B$2006,"<"&EDATE(N$6,1),Gastos!$C$7:$C$2006,"Gasto",Gastos!$D$7:$D$2006,"Nómina y honorarios") -> 0 | O20: =SUM(C20:N20) -> 0
B21: Renta | C21: =SUMIFS(Gastos!$H$7:$H$2006,Gastos!$B$7:$B$2006,">="&C$6,Gastos!$B$7:$B$2006,"<"&EDATE(C$6,1),Gastos!$C$7:$C$2006,"Gasto",Gastos!$D$7:$D$2006,"Renta") -> 0 | D21: =SUMIFS(Gastos!$H$7:$H$2006,Gastos!$B$7:$B$2006,">="&D$6,Gastos!$B$7:$B$2006,"<"&EDATE(D$6,1),Gastos!$C$7:$C$2006,"Gasto",Gastos!$D$7:$D$2006,"Renta") -> 0 | E21: =SUMIFS(Gastos!$H$7:$H$2006,Gastos!$B$7:$B$2006,">="&E$6,Gastos!$B$7:$B$2006,"<"&EDATE(E$6,1),Gastos!$C$7:$C$2006,"Gasto",Gastos!$D$7:$D$2006,"Renta") -> 0 | F21: =SUMIFS(Gastos!$H$7:$H$2006,Gastos!$B$7:$B$2006,">="&F$6,Gastos!$B$7:$B$2006,"<"&EDATE(F$6,1),Gastos!$C$7:$C$2006,"Gasto",Gastos!$D$7:$D$2006,"Renta") -> 0 | G21: =SUMIFS(Gastos!$H$7:$H$2006,Gastos!$B$7:$B$2006,">="&G$6,Gastos!$B$7:$B$2006,"<"&EDATE(G$6,1),Gastos!$C$7:$C$2006,"Gasto",Gastos!$D$7:$D$2006,"Renta") -> 0 | H21: =SUMIFS(Gastos!$H$7:$H$2006,Gastos!$B$7:$B$2006,">="&H$6,Gastos!$B$7:$B$2006,"<"&EDATE(H$6,1),Gastos!$C$7:$C$2006,"Gasto",Gastos!$D$7:$D$2006,"Renta") -> 0 | I21: =SUMIFS(Gastos!$H$7:$H$2006,Gastos!$B$7:$B$2006,">="&I$6,Gastos!$B$7:$B$2006,"<"&EDATE(I$6,1),Gastos!$C$7:$C$2006,"Gasto",Gastos!$D$7:$D$2006,"Renta") -> 0 | J21: =SUMIFS(Gastos!$H$7:$H$2006,Gastos!$B$7:$B$2006,">="&J$6,Gastos!$B$7:$B$2006,"<"&EDATE(J$6,1),Gastos!$C$7:$C$2006,"Gasto",Gastos!$D$7:$D$2006,"Renta") -> 0 | ... N21: =SUMIFS(Gastos!$H$7:$H$2006,Gastos!$B$7:$B$2006,">="&N$6,Gastos!$B$7:$B$2006,"<"&EDATE(N$6,1),Gastos!$C$7:$C$2006,"Gasto",Gastos!$D$7:$D$2006,"Renta") -> 0 | O21: =SUM(C21:N21) -> 0
B22: Marketing | C22: =SUMIFS(Gastos!$H$7:$H$2006,Gastos!$B$7:$B$2006,">="&C$6,Gastos!$B$7:$B$2006,"<"&EDATE(C$6,1),Gastos!$C$7:$C$2006,"Gasto",Gastos!$D$7:$D$2006,"Marketing") -> 0 | D22: =SUMIFS(Gastos!$H$7:$H$2006,Gastos!$B$7:$B$2006,">="&D$6,Gastos!$B$7:$B$2006,"<"&EDATE(D$6,1),Gastos!$C$7:$C$2006,"Gasto",Gastos!$D$7:$D$2006,"Marketing") -> 0 | E22: =SUMIFS(Gastos!$H$7:$H$2006,Gastos!$B$7:$B$2006,">="&E$6,Gastos!$B$7:$B$2006,"<"&EDATE(E$6,1),Gastos!$C$7:$C$2006,"Gasto",Gastos!$D$7:$D$2006,"Marketing") -> 0 | F22: =SUMIFS(Gastos!$H$7:$H$2006,Gastos!$B$7:$B$2006,">="&F$6,Gastos!$B$7:$B$2006,"<"&EDATE(F$6,1),Gastos!$C$7:$C$2006,"Gasto",Gastos!$D$7:$D$2006,"Marketing") -> 0 | G22: =SUMIFS(Gastos!$H$7:$H$2006,Gastos!$B$7:$B$2006,">="&G$6,Gastos!$B$7:$B$2006,"<"&EDATE(G$6,1),Gastos!$C$7:$C$2006,"Gasto",Gastos!$D$7:$D$2006,"Marketing") -> 0 | H22: =SUMIFS(Gastos!$H$7:$H$2006,Gastos!$B$7:$B$2006,">="&H$6,Gastos!$B$7:$B$2006,"<"&EDATE(H$6,1),Gastos!$C$7:$C$2006,"Gasto",Gastos!$D$7:$D$2006,"Marketing") -> 0 | I22: =SUMIFS(Gastos!$H$7:$H$2006,Gastos!$B$7:$B$2006,">="&I$6,Gastos!$B$7:$B$2006,"<"&EDATE(I$6,1),Gastos!$C$7:$C$2006,"Gasto",Gastos!$D$7:$D$2006,"Marketing") -> 0 | J22: =SUMIFS(Gastos!$H$7:$H$2006,Gastos!$B$7:$B$2006,">="&J$6,Gastos!$B$7:$B$2006,"<"&EDATE(J$6,1),Gastos!$C$7:$C$2006,"Gasto",Gastos!$D$7:$D$2006,"Marketing") -> 0 | ... N22: =SUMIFS(Gastos!$H$7:$H$2006,Gastos!$B$7:$B$2006,">="&N$6,Gastos!$B$7:$B$2006,"<"&EDATE(N$6,1),Gastos!$C$7:$C$2006,"Gasto",Gastos!$D$7:$D$2006,"Marketing") -> 0 | O22: =SUM(C22:N22) -> 0
B23: Servicios y software | C23: =SUMIFS(Gastos!$H$7:$H$2006,Gastos!$B$7:$B$2006,">="&C$6,Gastos!$B$7:$B$2006,"<"&EDATE(C$6,1),Gastos!$C$7:$C$2006,"Gasto",Gastos!$D$7:$D$2006,"Servicios y software") -> 0 | D23: =SUMIFS(Gastos!$H$7:$H$2006,Gastos!$B$7:$B$2006,">="&D$6,Gastos!$B$7:$B$2006,"<"&EDATE(D$6,1),Gastos!$C$7:$C$2006,"Gasto",Gastos!$D$7:$D$2006,"Servicios y software") -> 0 | E23: =SUMIFS(Gastos!$H$7:$H$2006,Gastos!$B$7:$B$2006,">="&E$6,Gastos!$B$7:$B$2006,"<"&EDATE(E$6,1),Gastos!$C$7:$C$2006,"Gasto",Gastos!$D$7:$D$2006,"Servicios y software") -> 0 | F23: =SUMIFS(Gastos!$H$7:$H$2006,Gastos!$B$7:$B$2006,">="&F$6,Gastos!$B$7:$B$2006,"<"&EDATE(F$6,1),Gastos!$C$7:$C$2006,"Gasto",Gastos!$D$7:$D$2006,"Servicios y software") -> 0 | G23: =SUMIFS(Gastos!$H$7:$H$2006,Gastos!$B$7:$B$2006,">="&G$6,Gastos!$B$7:$B$2006,"<"&EDATE(G$6,1),Gastos!$C$7:$C$2006,"Gasto",Gastos!$D$7:$D$2006,"Servicios y software") -> 0 | H23: =SUMIFS(Gastos!$H$7:$H$2006,Gastos!$B$7:$B$2006,">="&H$6,Gastos!$B$7:$B$2006,"<"&EDATE(H$6,1),Gastos!$C$7:$C$2006,"Gasto",Gastos!$D$7:$D$2006,"Servicios y software") -> 0 | I23: =SUMIFS(Gastos!$H$7:$H$2006,Gastos!$B$7:$B$2006,">="&I$6,Gastos!$B$7:$B$2006,"<"&EDATE(I$6,1),Gastos!$C$7:$C$2006,"Gasto",Gastos!$D$7:$D$2006,"Servicios y software") -> 0 | J23: =SUMIFS(Gastos!$H$7:$H$2006,Gastos!$B$7:$B$2006,">="&J$6,Gastos!$B$7:$B$2006,"<"&EDATE(J$6,1),Gastos!$C$7:$C$2006,"Gasto",Gastos!$D$7:$D$2006,"Servicios y software") -> 0 | ... N23: =SUMIFS(Gastos!$H$7:$H$2006,Gastos!$B$7:$B$2006,">="&N$6,Gastos!$B$7:$B$2006,"<"&EDATE(N$6,1),Gastos!$C$7:$C$2006,"Gasto",Gastos!$D$7:$D$2006,"Servicios y software") -> 0 | O23: =SUM(C23:N23) -> 0
B24: Mantenimiento | C24: =SUMIFS(Gastos!$H$7:$H$2006,Gastos!$B$7:$B$2006,">="&C$6,Gastos!$B$7:$B$2006,"<"&EDATE(C$6,1),Gastos!$C$7:$C$2006,"Gasto",Gastos!$D$7:$D$2006,"Mantenimiento") -> 0 | D24: =SUMIFS(Gastos!$H$7:$H$2006,Gastos!$B$7:$B$2006,">="&D$6,Gastos!$B$7:$B$2006,"<"&EDATE(D$6,1),Gastos!$C$7:$C$2006,"Gasto",Gastos!$D$7:$D$2006,"Mantenimiento") -> 0 | E24: =SUMIFS(Gastos!$H$7:$H$2006,Gastos!$B$7:$B$2006,">="&E$6,Gastos!$B$7:$B$2006,"<"&EDATE(E$6,1),Gastos!$C$7:$C$2006,"Gasto",Gastos!$D$7:$D$2006,"Mantenimiento") -> 0 | F24: =SUMIFS(Gastos!$H$7:$H$2006,Gastos!$B$7:$B$2006,">="&F$6,Gastos!$B$7:$B$2006,"<"&EDATE(F$6,1),Gastos!$C$7:$C$2006,"Gasto",Gastos!$D$7:$D$2006,"Mantenimiento") -> 0 | G24: =SUMIFS(Gastos!$H$7:$H$2006,Gastos!$B$7:$B$2006,">="&G$6,Gastos!$B$7:$B$2006,"<"&EDATE(G$6,1),Gastos!$C$7:$C$2006,"Gasto",Gastos!$D$7:$D$2006,"Mantenimiento") -> 0 | H24: =SUMIFS(Gastos!$H$7:$H$2006,Gastos!$B$7:$B$2006,">="&H$6,Gastos!$B$7:$B$2006,"<"&EDATE(H$6,1),Gastos!$C$7:$C$2006,"Gasto",Gastos!$D$7:$D$2006,"Mantenimiento") -> 0 | I24: =SUMIFS(Gastos!$H$7:$H$2006,Gastos!$B$7:$B$2006,">="&I$6,Gastos!$B$7:$B$2006,"<"&EDATE(I$6,1),Gastos!$C$7:$C$2006,"Gasto",Gastos!$D$7:$D$2006,"Mantenimiento") -> 0 | J24: =SUMIFS(Gastos!$H$7:$H$2006,Gastos!$B$7:$B$2006,">="&J$6,Gastos!$B$7:$B$2006,"<"&EDATE(J$6,1),Gastos!$C$7:$C$2006,"Gasto",Gastos!$D$7:$D$2006,"Mantenimiento") -> 0 | ... N24: =SUMIFS(Gastos!$H$7:$H$2006,Gastos!$B$7:$B$2006,">="&N$6,Gastos!$B$7:$B$2006,"<"&EDATE(N$6,1),Gastos!$C$7:$C$2006,"Gasto",Gastos!$D$7:$D$2006,"Mantenimiento") -> 0 | O24: =SUM(C24:N24) -> 0
B25: Otros gastos operativos | C25: =SUMIFS(Gastos!$H$7:$H$2006,Gastos!$B$7:$B$2006,">="&C$6,Gastos!$B$7:$B$2006,"<"&EDATE(C$6,1),Gastos!$C$7:$C$2006,"Gasto",Gastos!$D$7:$D$2006,"Otros") -> 0 | D25: =SUMIFS(Gastos!$H$7:$H$2006,Gastos!$B$7:$B$2006,">="&D$6,Gastos!$B$7:$B$2006,"<"&EDATE(D$6,1),Gastos!$C$7:$C$2006,"Gasto",Gastos!$D$7:$D$2006,"Otros") -> 0 | E25: =SUMIFS(Gastos!$H$7:$H$2006,Gastos!$B$7:$B$2006,">="&E$6,Gastos!$B$7:$B$2006,"<"&EDATE(E$6,1),Gastos!$C$7:$C$2006,"Gasto",Gastos!$D$7:$D$2006,"Otros") -> 0 | F25: =SUMIFS(Gastos!$H$7:$H$2006,Gastos!$B$7:$B$2006,">="&F$6,Gastos!$B$7:$B$2006,"<"&EDATE(F$6,1),Gastos!$C$7:$C$2006,"Gasto",Gastos!$D$7:$D$2006,"Otros") -> 0 | G25: =SUMIFS(Gastos!$H$7:$H$2006,Gastos!$B$7:$B$2006,">="&G$6,Gastos!$B$7:$B$2006,"<"&EDATE(G$6,1),Gastos!$C$7:$C$2006,"Gasto",Gastos!$D$7:$D$2006,"Otros") -> 0 | H25: =SUMIFS(Gastos!$H$7:$H$2006,Gastos!$B$7:$B$2006,">="&H$6,Gastos!$B$7:$B$2006,"<"&EDATE(H$6,1),Gastos!$C$7:$C$2006,"Gasto",Gastos!$D$7:$D$2006,"Otros") -> 0 | I25: =SUMIFS(Gastos!$H$7:$H$2006,Gastos!$B$7:$B$2006,">="&I$6,Gastos!$B$7:$B$2006,"<"&EDATE(I$6,1),Gastos!$C$7:$C$2006,"Gasto",Gastos!$D$7:$D$2006,"Otros") -> 0 | J25: =SUMIFS(Gastos!$H$7:$H$2006,Gastos!$B$7:$B$2006,">="&J$6,Gastos!$B$7:$B$2006,"<"&EDATE(J$6,1),Gastos!$C$7:$C$2006,"Gasto",Gastos!$D$7:$D$2006,"Otros") -> 0 | ... N25: =SUMIFS(Gastos!$H$7:$H$2006,Gastos!$B$7:$B$2006,">="&N$6,Gastos!$B$7:$B$2006,"<"&EDATE(N$6,1),Gastos!$C$7:$C$2006,"Gasto",Gastos!$D$7:$D$2006,"Otros") -> 0 | O25: =SUM(C25:N25) -> 0
B26: Gastos operativos | C26: =SUM(C19:C25) -> 0 | D26: =SUM(D19:D25) -> 0 | E26: =SUM(E19:E25) -> 0 | F26: =SUM(F19:F25) -> 0 | G26: =SUM(G19:G25) -> 0 | H26: =SUM(H19:H25) -> 0 | I26: =SUM(I19:I25) -> 0 | J26: =SUM(J19:J25) -> 0 | ... N26: =SUM(N19:N25) -> 0 | O26: =SUM(C26:N26) -> 0
B27: Resultado antes de depreciación | C27: =C17-C26 -> 2200 | D27: =D17-D26 -> 0 | E27: =E17-E26 -> 0 | F27: =F17-F26 -> 0 | G27: =G17-G26 -> 0 | H27: =H17-H26 -> 0 | I27: =I17-I26 -> 0 | J27: =J17-J26 -> 0 | ... N27: =N17-N26 -> 0 | O27: =SUM(C27:N27) -> 2200
B28: Depreciación contable | C28: =SUM(Activos!M7:M106) -> 0 | D28: =SUM(Activos!N7:N106) -> 0 | E28: =SUM(Activos!O7:O106) -> 0 | F28: =SUM(Activos!P7:P106) -> 0 | G28: =SUM(Activos!Q7:Q106) -> 0 | H28: =SUM(Activos!R7:R106) -> 0 | I28: =SUM(Activos!S7:S106) -> 0 | J28: =SUM(Activos!T7:T106) -> 0 | ... N28: =SUM(Activos!X7:X106) -> 0 | O28: =SUM(C28:N28) -> 0
B29: Utilidad operativa | C29: =C27-C28 -> 2200 | D29: =D27-D28 -> 0 | E29: =E27-E28 -> 0 | F29: =F27-F28 -> 0 | G29: =G27-G28 -> 0 | H29: =H27-H28 -> 0 | I29: =I27-I28 -> 0 | J29: =J27-J28 -> 0 | ... N29: =N27-N28 -> 0 | O29: =SUM(C29:N29) -> 2200
B30: Intereses | C30: =SUMIFS(Gastos!$H$7:$H$2006,Gastos!$B$7:$B$2006,">="&C$6,Gastos!$B$7:$B$2006,"<"&EDATE(C$6,1),Gastos!$C$7:$C$2006,"Gasto",Gastos!$D$7:$D$2006,"Intereses") -> 0 | D30: =SUMIFS(Gastos!$H$7:$H$2006,Gastos!$B$7:$B$2006,">="&D$6,Gastos!$B$7:$B$2006,"<"&EDATE(D$6,1),Gastos!$C$7:$C$2006,"Gasto",Gastos!$D$7:$D$2006,"Intereses") -> 0 | E30: =SUMIFS(Gastos!$H$7:$H$2006,Gastos!$B$7:$B$2006,">="&E$6,Gastos!$B$7:$B$2006,"<"&EDATE(E$6,1),Gastos!$C$7:$C$2006,"Gasto",Gastos!$D$7:$D$2006,"Intereses") -> 0 | F30: =SUMIFS(Gastos!$H$7:$H$2006,Gastos!$B$7:$B$2006,">="&F$6,Gastos!$B$7:$B$2006,"<"&EDATE(F$6,1),Gastos!$C$7:$C$2006,"Gasto",Gastos!$D$7:$D$2006,"Intereses") -> 0 | G30: =SUMIFS(Gastos!$H$7:$H$2006,Gastos!$B$7:$B$2006,">="&G$6,Gastos!$B$7:$B$2006,"<"&EDATE(G$6,1),Gastos!$C$7:$C$2006,"Gasto",Gastos!$D$7:$D$2006,"Intereses") -> 0 | H30: =SUMIFS(Gastos!$H$7:$H$2006,Gastos!$B$7:$B$2006,">="&H$6,Gastos!$B$7:$B$2006,"<"&EDATE(H$6,1),Gastos!$C$7:$C$2006,"Gasto",Gastos!$D$7:$D$2006,"Intereses") -> 0 | I30: =SUMIFS(Gastos!$H$7:$H$2006,Gastos!$B$7:$B$2006,">="&I$6,Gastos!$B$7:$B$2006,"<"&EDATE(I$6,1),Gastos!$C$7:$C$2006,"Gasto",Gastos!$D$7:$D$2006,"Intereses") -> 0 | J30: =SUMIFS(Gastos!$H$7:$H$2006,Gastos!$B$7:$B$2006,">="&J$6,Gastos!$B$7:$B$2006,"<"&EDATE(J$6,1),Gastos!$C$7:$C$2006,"Gasto",Gastos!$D$7:$D$2006,"Intereses") -> 0 | ... N30: =SUMIFS(Gastos!$H$7:$H$2006,Gastos!$B$7:$B$2006,">="&N$6,Gastos!$B$7:$B$2006,"<"&EDATE(N$6,1),Gastos!$C$7:$C$2006,"Gasto",Gastos!$D$7:$D$2006,"Intereses") -> 0 | O30: =SUM(C30:N30) -> 0
B31: Utilidad antes de ISR | C31: =C29-C30 -> 2200 | D31: =D29-D30 -> 0 | E31: =E29-E30 -> 0 | F31: =F29-F30 -> 0 | G31: =G29-G30 -> 0 | H31: =H29-H30 -> 0 | I31: =I29-I30 -> 0 | J31: =J29-J30 -> 0 | ... N31: =N29-N30 -> 0 | O31: =SUM(C31:N31) -> 2200
B32: ISR devengado (capturado) | C32: =SUMIFS(Gastos!$H$7:$H$2006,Gastos!$B$7:$B$2006,">="&C$6,Gastos!$B$7:$B$2006,"<"&EDATE(C$6,1),Gastos!$C$7:$C$2006,"ISR devengado") -> 0 | D32: =SUMIFS(Gastos!$H$7:$H$2006,Gastos!$B$7:$B$2006,">="&D$6,Gastos!$B$7:$B$2006,"<"&EDATE(D$6,1),Gastos!$C$7:$C$2006,"ISR devengado") -> 0 | E32: =SUMIFS(Gastos!$H$7:$H$2006,Gastos!$B$7:$B$2006,">="&E$6,Gastos!$B$7:$B$2006,"<"&EDATE(E$6,1),Gastos!$C$7:$C$2006,"ISR devengado") -> 0 | F32: =SUMIFS(Gastos!$H$7:$H$2006,Gastos!$B$7:$B$2006,">="&F$6,Gastos!$B$7:$B$2006,"<"&EDATE(F$6,1),Gastos!$C$7:$C$2006,"ISR devengado") -> 0 | G32: =SUMIFS(Gastos!$H$7:$H$2006,Gastos!$B$7:$B$2006,">="&G$6,Gastos!$B$7:$B$2006,"<"&EDATE(G$6,1),Gastos!$C$7:$C$2006,"ISR devengado") -> 0 | H32: =SUMIFS(Gastos!$H$7:$H$2006,Gastos!$B$7:$B$2006,">="&H$6,Gastos!$B$7:$B$2006,"<"&EDATE(H$6,1),Gastos!$C$7:$C$2006,"ISR devengado") -> 0 | I32: =SUMIFS(Gastos!$H$7:$H$2006,Gastos!$B$7:$B$2006,">="&I$6,Gastos!$B$7:$B$2006,"<"&EDATE(I$6,1),Gastos!$C$7:$C$2006,"ISR devengado") -> 0 | J32: =SUMIFS(Gastos!$H$7:$H$2006,Gastos!$B$7:$B$2006,">="&J$6,Gastos!$B$7:$B$2006,"<"&EDATE(J$6,1),Gastos!$C$7:$C$2006,"ISR devengado") -> 0 | ... N32: =SUMIFS(Gastos!$H$7:$H$2006,Gastos!$B$7:$B$2006,">="&N$6,Gastos!$B$7:$B$2006,"<"&EDATE(N$6,1),Gastos!$C$7:$C$2006,"ISR devengado") -> 0 | O32: =SUM(C32:N32) -> 0
B33: Utilidad neta | C33: =C31-C32 -> 2200 | D33: =D31-D32 -> 0 | E33: =E31-E32 -> 0 | F33: =F31-F32 -> 0 | G33: =G31-G32 -> 0 | H33: =H31-H32 -> 0 | I33: =I31-I32 -> 0 | J33: =J31-J32 -> 0 | ... N33: =N31-N32 -> 0 | O33: =SUM(C33:N33) -> 2200
B35: Retiros familiares (fuera de gastos) | C35: ='Flujo de Efectivo'!C20 -> 0 | D35: ='Flujo de Efectivo'!D20 -> 0 | E35: ='Flujo de Efectivo'!E20 -> 0 | F35: ='Flujo de Efectivo'!F20 -> 0 | G35: ='Flujo de Efectivo'!G20 -> 0 | H35: ='Flujo de Efectivo'!H20 -> 0 | I35: ='Flujo de Efectivo'!I20 -> 0 | J35: ='Flujo de Efectivo'!J20 -> 0 | ... N35: ='Flujo de Efectivo'!N20 -> 0 | O35: =SUM(C35:N35) -> 0
B36: Utilidad menos retiros* | C36: =C33-C35 -> 2200 | D36: =D33-D35 -> 0 | E36: =E33-E35 -> 0 | F36: =F33-F35 -> 0 | G36: =G33-G35 -> 0 | H36: =H33-H35 -> 0 | I36: =I33-I35 -> 0 | J36: =J33-J35 -> 0 | ... N36: =N33-N35 -> 0 | O36: =SUM(C36:N36) -> 2200
B38: *No equivale al efectivo disponible.

Sheet Balance General
B2: Balance General
B4: MXN · enero a diciembre
B6: Concepto | C6: =DATE(Configuración!$C$5,1,1) -> 46023 | D6: =DATE(Configuración!$C$5,2,1) -> 46054 | E6: =DATE(Configuración!$C$5,3,1) -> 46082 | F6: =DATE(Configuración!$C$5,4,1) -> 46113 | G6: =DATE(Configuración!$C$5,5,1) -> 46143 | H6: =DATE(Configuración!$C$5,6,1) -> 46174 | I6: =DATE(Configuración!$C$5,7,1) -> 46204 | J6: =DATE(Configuración!$C$5,8,1) -> 46235 | K6: =DATE(Configuración!$C$5,9,1) -> 46266 | L6: =DATE(Configuración!$C$5,10,1) -> 46296 | M6: =DATE(Configuración!$C$5,11,1) -> 46327 | N6: =DATE(Configuración!$C$5,12,1) -> 46357 | O6: Cierre anual
B7: Efectivo y bancos | C7: ='Flujo de Efectivo'!C25 -> 2200 | D7: ='Flujo de Efectivo'!D25 -> 2200 | E7: ='Flujo de Efectivo'!E25 -> 2200 | F7: ='Flujo de Efectivo'!F25 -> 2200 | G7: ='Flujo de Efectivo'!G25 -> 2200 | H7: ='Flujo de Efectivo'!H25 -> 2200 | I7: ='Flujo de Efectivo'!I25 -> 2200 | J7: ='Flujo de Efectivo'!J25 -> 2200 | ... N7: ='Flujo de Efectivo'!N25 -> 2200 | O7: =N7 -> 2200
B8: Cuentas por cobrar | C8: =Configuración!$C$10+SUMIFS(Ingresos!$K$7:$K$2006,Ingresos!$B$7:$B$2006,">="&C$6,Ingresos!$B$7:$B$2006,"<"&EDATE(C$6,1),Ingresos!$C$7:$C$2006,"Servicio")-'Flujo de Efectivo'!C7-C41-C42-C43 -> 0 | D8: =C8+SUMIFS(Ingresos!$K$7:$K$2006,Ingresos!$B$7:$B$2006,">="&D$6,Ingresos!$B$7:$B$2006,"<"&EDATE(D$6,1),Ingresos!$C$7:$C$2006,"Servicio")-'Flujo de Efectivo'!D7-D41-D42-D43 -> 0 | E8: =D8+SUMIFS(Ingresos!$K$7:$K$2006,Ingresos!$B$7:$B$2006,">="&E$6,Ingresos!$B$7:$B$2006,"<"&EDATE(E$6,1),Ingresos!$C$7:$C$2006,"Servicio")-'Flujo de Efectivo'!E7-E41-E42-E43 -> 0 | F8: =E8+SUMIFS(Ingresos!$K$7:$K$2006,Ingresos!$B$7:$B$2006,">="&F$6,Ingresos!$B$7:$B$2006,"<"&EDATE(F$6,1),Ingresos!$C$7:$C$2006,"Servicio")-'Flujo de Efectivo'!F7-F41-F42-F43 -> 0 | G8: =F8+SUMIFS(Ingresos!$K$7:$K$2006,Ingresos!$B$7:$B$2006,">="&G$6,Ingresos!$B$7:$B$2006,"<"&EDATE(G$6,1),Ingresos!$C$7:$C$2006,"Servicio")-'Flujo de Efectivo'!G7-G41-G42-G43 -> 0 | H8: =G8+SUMIFS(Ingresos!$K$7:$K$2006,Ingresos!$B$7:$B$2006,">="&H$6,Ingresos!$B$7:$B$2006,"<"&EDATE(H$6,1),Ingresos!$C$7:$C$2006,"Servicio")-'Flujo de Efectivo'!H7-H41-H42-H43 -> 0 | I8: =H8+SUMIFS(Ingresos!$K$7:$K$2006,Ingresos!$B$7:$B$2006,">="&I$6,Ingresos!$B$7:$B$2006,"<"&EDATE(I$6,1),Ingresos!$C$7:$C$2006,"Servicio")-'Flujo de Efectivo'!I7-I41-I42-I43 -> 0 | J8: =I8+SUMIFS(Ingresos!$K$7:$K$2006,Ingresos!$B$7:$B$2006,">="&J$6,Ingresos!$B$7:$B$2006,"<"&EDATE(J$6,1),Ingresos!$C$7:$C$2006,"Servicio")-'Flujo de Efectivo'!J7-J41-J42-J43 -> 0 | K8: =J8+SUMIFS(Ingresos!$K$7:$K$2006,Ingresos!$B$7:$B$2006,">="&K$6,Ingresos!$B$7:$B$2006,"<"&EDATE(K$6,1),Ingresos!$C$7:$C$2006,"Servicio")-'Flujo de Efectivo'!K7-K41-K42-K43 -> 0 | ... N8: =M8+SUMIFS(Ingresos!$K$7:$K$2006,Ingresos!$B$7:$B$2006,">="&N$6,Ingresos!$B$7:$B$2006,"<"&EDATE(N$6,1),Ingresos!$C$7:$C$2006,"Servicio")-'Flujo de Efectivo'!N7-N41-N42-N43 -> 0 | O8: =N8 -> 0
B9: IVA neto a favor | C9: =MAX(0,-C38) -> 0 | D9: =MAX(0,-D38) -> 0 | E9: =MAX(0,-E38) -> 0 | F9: =MAX(0,-F38) -> 0 | G9: =MAX(0,-G38) -> 0 | H9: =MAX(0,-H38) -> 0 | I9: =MAX(0,-I38) -> 0 | J9: =MAX(0,-J38) -> 0 | ... N9: =MAX(0,-N38) -> 0 | O9: =N9 -> 0
B10: Retenciones ISR a favor | C10: =Configuración!$C$12+C42-C44 -> 0 | D10: =C10+D42-D44 -> 0 | E10: =D10+E42-E44 -> 0 | F10: =E10+F42-F44 -> 0 | G10: =F10+G42-G44 -> 0 | H10: =G10+H42-H44 -> 0 | I10: =H10+I42-I44 -> 0 | J10: =I10+J42-J44 -> 0 | K10: =J10+K42-K44 -> 0 | ... N10: =M10+N42-N44 -> 0 | O10: =N10 -> 0
B11: Retenciones IVA a favor | C11: =Configuración!$C$13+C43-C45 -> 0 | D11: =C11+D43-D45 -> 0 | E11: =D11+E43-E45 -> 0 | F11: =E11+F43-F45 -> 0 | G11: =F11+G43-G45 -> 0 | H11: =G11+H43-H45 -> 0 | I11: =H11+I43-I45 -> 0 | J11: =I11+J43-J45 -> 0 | K11: =J11+K43-K45 -> 0 | ... N11: =M11+N43-N45 -> 0 | O11: =N11 -> 0
B12: Activo circulante | C12: =SUM(C7:C11) -> 2200 | D12: =SUM(D7:D11) -> 2200 | E12: =SUM(E7:E11) -> 2200 | F12: =SUM(F7:F11) -> 2200 | G12: =SUM(G7:G11) -> 2200 | H12: =SUM(H7:H11) -> 2200 | I12: =SUM(I7:I11) -> 2200 | J12: =SUM(J7:J11) -> 2200 | ... N12: =SUM(N7:N11) -> 2200 | O12: =N12 -> 2200
B14: Activos fijos a costo | C14: =SUMIFS(Activos!$E$7:$E$106,Activos!$C$7:$C$106,"<"&DATE(Configuración!$C$5,1,1),Activos!$C$7:$C$106,">0")+C39 -> 0 | D14: =C14+D39 -> 0 | E14: =D14+E39 -> 0 | F14: =E14+F39 -> 0 | G14: =F14+G39 -> 0 | H14: =G14+H39 -> 0 | I14: =H14+I39 -> 0 | J14: =I14+J39 -> 0 | K14: =J14+K39 -> 0 | ... N14: =M14+N39 -> 0 | O14: =N14 -> 0
B15: Depreciación acumulada | C15: =SUMIFS(Activos!$I$7:$I$106,Activos!$C$7:$C$106,"<"&DATE(Configuración!$C$5,1,1),Activos!$C$7:$C$106,">0")+'Estado de Resultados'!C28 -> 0 | D15: =C15+'Estado de Resultados'!D28 -> 0 | E15: =D15+'Estado de Resultados'!E28 -> 0 | F15: =E15+'Estado de Resultados'!F28 -> 0 | G15: =F15+'Estado de Resultados'!G28 -> 0 | H15: =G15+'Estado de Resultados'!H28 -> 0 | I15: =H15+'Estado de Resultados'!I28 -> 0 | J15: =I15+'Estado de Resultados'!J28 -> 0 | K15: =J15+'Estado de Resultados'!K28 -> 0 | ... N15: =M15+'Estado de Resultados'!N28 -> 0 | O15: =N15 -> 0
B16: Activos fijos netos | C16: =C14-C15 -> 0 | D16: =D14-D15 -> 0 | E16: =E14-E15 -> 0 | F16: =F14-F15 -> 0 | G16: =G14-G15 -> 0 | H16: =H14-H15 -> 0 | I16: =I14-I15 -> 0 | J16: =J14-J15 -> 0 | ... N16: =N14-N15 -> 0 | O16: =N16 -> 0
B17: Total activo | C17: =C12+C16 -> 2200 | D17: =D12+D16 -> 2200 | E17: =E12+E16 -> 2200 | F17: =F12+F16 -> 2200 | G17: =G12+G16 -> 2200 | H17: =H12+H16 -> 2200 | I17: =I12+I16 -> 2200 | J17: =J12+J16 -> 2200 | ... N17: =N12+N16 -> 2200 | O17: =N17 -> 2200
B19: Proveedores y otras cuentas por pagar | C19: =Configuración!$C$14+SUMIFS(Gastos!$K$7:$K$2006,Gastos!$B$7:$B$2006,">="&C$6,Gastos!$B$7:$B$2006,"<"&EDATE(C$6,1),Gastos!$C$7:$C$2006,"Gasto")+C39+C40-'Flujo de Efectivo'!C9-'Flujo de Efectivo'!C14 -> 0 | D19: =C19+SUMIFS(Gastos!$K$7:$K$2006,Gastos!$B$7:$B$2006,">="&D$6,Gastos!$B$7:$B$2006,"<"&EDATE(D$6,1),Gastos!$C$7:$C$2006,"Gasto")+D39+D40-'Flujo de Efectivo'!D9-'Flujo de Efectivo'!D14 -> 0 | E19: =D19+SUMIFS(Gastos!$K$7:$K$2006,Gastos!$B$7:$B$2006,">="&E$6,Gastos!$B$7:$B$2006,"<"&EDATE(E$6,1),Gastos!$C$7:$C$2006,"Gasto")+E39+E40-'Flujo de Efectivo'!E9-'Flujo de Efectivo'!E14 -> 0 | F19: =E19+SUMIFS(Gastos!$K$7:$K$2006,Gastos!$B$7:$B$2006,">="&F$6,Gastos!$B$7:$B$2006,"<"&EDATE(F$6,1),Gastos!$C$7:$C$2006,"Gasto")+F39+F40-'Flujo de Efectivo'!F9-'Flujo de Efectivo'!F14 -> 0 | G19: =F19+SUMIFS(Gastos!$K$7:$K$2006,Gastos!$B$7:$B$2006,">="&G$6,Gastos!$B$7:$B$2006,"<"&EDATE(G$6,1),Gastos!$C$7:$C$2006,"Gasto")+G39+G40-'Flujo de Efectivo'!G9-'Flujo de Efectivo'!G14 -> 0 | H19: =G19+SUMIFS(Gastos!$K$7:$K$2006,Gastos!$B$7:$B$2006,">="&H$6,Gastos!$B$7:$B$2006,"<"&EDATE(H$6,1),Gastos!$C$7:$C$2006,"Gasto")+H39+H40-'Flujo de Efectivo'!H9-'Flujo de Efectivo'!H14 -> 0 | I19: =H19+SUMIFS(Gastos!$K$7:$K$2006,Gastos!$B$7:$B$2006,">="&I$6,Gastos!$B$7:$B$2006,"<"&EDATE(I$6,1),Gastos!$C$7:$C$2006,"Gasto")+I39+I40-'Flujo de Efectivo'!I9-'Flujo de Efectivo'!I14 -> 0 | J19: =I19+SUMIFS(Gastos!$K$7:$K$2006,Gastos!$B$7:$B$2006,">="&J$6,Gastos!$B$7:$B$2006,"<"&EDATE(J$6,1),Gastos!$C$7:$C$2006,"Gasto")+J39+J40-'Flujo de Efectivo'!J9-'Flujo de Efectivo'!J14 -> 0 | K19: =J19+SUMIFS(Gastos!$K$7:$K$2006,Gastos!$B$7:$B$2006,">="&K$6,Gastos!$B$7:$B$2006,"<"&EDATE(K$6,1),Gastos!$C$7:$C$2006,"Gasto")+K39+K40-'Flujo de Efectivo'!K9-'Flujo de Efectivo'!K14 -> 0 | ... N19: =M19+SUMIFS(Gastos!$K$7:$K$2006,Gastos!$B$7:$B$2006,">="&N$6,Gastos!$B$7:$B$2006,"<"&EDATE(N$6,1),Gastos!$C$7:$C$2006,"Gasto")+N39+N40-'Flujo de Efectivo'!N9-'Flujo de Efectivo'!N14 -> 0 | O19: =N19 -> 0
B20: Anticipos de pacientes | C20: =Configuración!$C$15+'Flujo de Efectivo'!C8-C41 -> 0 | D20: =C20+'Flujo de Efectivo'!D8-D41 -> 0 | E20: =D20+'Flujo de Efectivo'!E8-E41 -> 0 | F20: =E20+'Flujo de Efectivo'!F8-F41 -> 0 | G20: =F20+'Flujo de Efectivo'!G8-G41 -> 0 | H20: =G20+'Flujo de Efectivo'!H8-H41 -> 0 | I20: =H20+'Flujo de Efectivo'!I8-I41 -> 0 | J20: =I20+'Flujo de Efectivo'!J8-J41 -> 0 | K20: =J20+'Flujo de Efectivo'!K8-K41 -> 0 | ... N20: =M20+'Flujo de Efectivo'!N8-N41 -> 0 | O20: =N20 -> 0
B21: IVA neto por pagar | C21: =MAX(0,C38) -> 0 | D21: =MAX(0,D38) -> 0 | E21: =MAX(0,E38) -> 0 | F21: =MAX(0,F38) -> 0 | G21: =MAX(0,G38) -> 0 | H21: =MAX(0,H38) -> 0 | I21: =MAX(0,I38) -> 0 | J21: =MAX(0,J38) -> 0 | ... N21: =MAX(0,N38) -> 0 | O21: =N21 -> 0
B22: ISR por pagar | C22: =Configuración!$C$17+'Estado de Resultados'!C32-'Flujo de Efectivo'!C10-C44 -> 0 | D22: =C22+'Estado de Resultados'!D32-'Flujo de Efectivo'!D10-D44 -> 0 | E22: =D22+'Estado de Resultados'!E32-'Flujo de Efectivo'!E10-E44 -> 0 | F22: =E22+'Estado de Resultados'!F32-'Flujo de Efectivo'!F10-F44 -> 0 | G22: =F22+'Estado de Resultados'!G32-'Flujo de Efectivo'!G10-G44 -> 0 | H22: =G22+'Estado de Resultados'!H32-'Flujo de Efectivo'!H10-H44 -> 0 | I22: =H22+'Estado de Resultados'!I32-'Flujo de Efectivo'!I10-I44 -> 0 | J22: =I22+'Estado de Resultados'!J32-'Flujo de Efectivo'!J10-J44 -> 0 | K22: =J22+'Estado de Resultados'!K32-'Flujo de Efectivo'!K10-K44 -> 0 | ... N22: =M22+'Estado de Resultados'!N32-'Flujo de Efectivo'!N10-N44 -> 0 | O22: =N22 -> 0
B23: Préstamos a corto plazo | C23: =SUMIFS(Pasivos!$G$7:$G$506,Pasivos!$C$7:$C$506,"Saldo inicial",Pasivos!$F$7:$F$506,"Corto plazo",Pasivos!$B$7:$B$506,DATE(Configuración!$C$5,1,1)-1)+SUMIFS(Pasivos!$G$7:$G$506,Pasivos!$B$7:$B$506,">="&C$6,Pasivos!$B$7:$B$506,"<"&EDATE(C$6,1),Pasivos!$C$7:$C$506,"Desembolso",Pasivos!$F$7:$F$506,"Corto plazo")-SUMIFS(Pasivos!$G$7:$G$506,Pasivos!$B$7:$B$506,">="&C$6,Pasivos!$B$7:$B$506,"<"&EDATE(C$6,1),Pasivos!$C$7:$C$506,"Amortización",Pasivos!$F$7:$F$506,"Corto plazo")+1*(SUMIFS(Pasivos!$G$7:$G$506,Pasivos!$B$7:$B$506,">="&C$6,Pasivos!$B$7:$B$506,"<"&EDATE(C$6,1),Pasivos!$C$7:$C$506,"Reclasificar a CP")-SUMIFS(Pasivos!$G$7:$G$506,Pasivos!$B$7:$B$506,">="&C$6,Pasivos!$B$7:$B$506,"<"&EDATE(C$6,1),Pasivos!$C$7:$C$506,"Reclasificar a LP")) -> 0 | D23: =C23+SUMIFS(Pasivos!$G$7:$G$506,Pasivos!$B$7:$B$506,">="&D$6,Pasivos!$B$7:$B$506,"<"&EDATE(D$6,1),Pasivos!$C$7:$C$506,"Desembolso",Pasivos!$F$7:$F$506,"Corto plazo")-SUMIFS(Pasivos!$G$7:$G$506,Pasivos!$B$7:$B$506,">="&D$6,Pasivos!$B$7:$B$506,"<"&EDATE(D$6,1),Pasivos!$C$7:$C$506,"Amortización",Pasivos!$F$7:$F$506,"Corto plazo")+1*(SUMIFS(Pasivos!$G$7:$G$506,Pasivos!$B$7:$B$506,">="&D$6,Pasivos!$B$7:$B$506,"<"&EDATE(D$6,1),Pasivos!$C$7:$C$506,"Reclasificar a CP")-SUMIFS(Pasivos!$G$7:$G$506,Pasivos!$B$7:$B$506,">="&D$6,Pasivos!$B$7:$B$506,"<"&EDATE(D$6,1),Pasivos!$C$7:$C$506,"Reclasificar a LP")) -> 0 | E23: =D23+SUMIFS(Pasivos!$G$7:$G$506,Pasivos!$B$7:$B$506,">="&E$6,Pasivos!$B$7:$B$506,"<"&EDATE(E$6,1),Pasivos!$C$7:$C$506,"Desembolso",Pasivos!$F$7:$F$506,"Corto plazo")-SUMIFS(Pasivos!$G$7:$G$506,Pasivos!$B$7:$B$506,">="&E$6,Pasivos!$B$7:$B$506,"<"&EDATE(E$6,1),Pasivos!$C$7:$C$506,"Amortización",Pasivos!$F$7:$F$506,"Corto plazo")+1*(SUMIFS(Pasivos!$G$7:$G$506,Pasivos!$B$7:$B$506,">="&E$6,Pasivos!$B$7:$B$506,"<"&EDATE(E$6,1),Pasivos!$C$7:$C$506,"Reclasificar a CP")-SUMIFS(Pasivos!$G$7:$G$506,Pasivos!$B$7:$B$506,">="&E$6,Pasivos!$B$7:$B$506,"<"&EDATE(E$6,1),Pasivos!$C$7:$C$506,"Reclasificar a LP")) -> 0 | F23: =E23+SUMIFS(Pasivos!$G$7:$G$506,Pasivos!$B$7:$B$506,">="&F$6,Pasivos!$B$7:$B$506,"<"&EDATE(F$6,1),Pasivos!$C$7:$C$506,"Desembolso",Pasivos!$F$7:$F$506,"Corto plazo")-SUMIFS(Pasivos!$G$7:$G$506,Pasivos!$B$7:$B$506,">="&F$6,Pasivos!$B$7:$B$506,"<"&EDATE(F$6,1),Pasivos!$C$7:$C$506,"Amortización",Pasivos!$F$7:$F$506,"Corto plazo")+1*(SUMIFS(Pasivos!$G$7:$G$506,Pasivos!$B$7:$B$506,">="&F$6,Pasivos!$B$7:$B$506,"<"&EDATE(F$6,1),Pasivos!$C$7:$C$506,"Reclasificar a CP")-SUMIFS(Pasivos!$G$7:$G$506,Pasivos!$B$7:$B$506,">="&F$6,Pasivos!$B$7:$B$506,"<"&EDATE(F$6,1),Pasivos!$C$7:$C$506,"Reclasificar a LP")) -> 0 | G23: =F23+SUMIFS(Pasivos!$G$7:$G$506,Pasivos!$B$7:$B$506,">="&G$6,Pasivos!$B$7:$B$506,"<"&EDATE(G$6,1),Pasivos!$C$7:$C$506,"Desembolso",Pasivos!$F$7:$F$506,"Corto plazo")-SUMIFS(Pasivos!$G$7:$G$506,Pasivos!$B$7:$B$506,">="&G$6,Pasivos!$B$7:$B$506,"<"&EDATE(G$6,1),Pasivos!$C$7:$C$506,"Amortización",Pasivos!$F$7:$F$506,"Corto plazo")+1*(SUMIFS(Pasivos!$G$7:$G$506,Pasivos!$B$7:$B$506,">="&G$6,Pasivos!$B$7:$B$506,"<"&EDATE(G$6,1),Pasivos!$C$7:$C$506,"Reclasificar a CP")-SUMIFS(Pasivos!$G$7:$G$506,Pasivos!$B$7:$B$506,">="&G$6,Pasivos!$B$7:$B$506,"<"&EDATE(G$6,1),Pasivos!$C$7:$C$506,"Reclasificar a LP")) -> 0 | H23: =G23+SUMIFS(Pasivos!$G$7:$G$506,Pasivos!$B$7:$B$506,">="&H$6,Pasivos!$B$7:$B$506,"<"&EDATE(H$6,1),Pasivos!$C$7:$C$506,"Desembolso",Pasivos!$F$7:$F$506,"Corto plazo")-SUMIFS(Pasivos!$G$7:$G$506,Pasivos!$B$7:$B$506,">="&H$6,Pasivos!$B$7:$B$506,"<"&EDATE(H$6,1),Pasivos!$C$7:$C$506,"Amortización",Pasivos!$F$7:$F$506,"Corto plazo")+1*(SUMIFS(Pasivos!$G$7:$G$506,Pasivos!$B$7:$B$506,">="&H$6,Pasivos!$B$7:$B$506,"<"&EDATE(H$6,1),Pasivos!$C$7:$C$506,"Reclasificar a CP")-SUMIFS(Pasivos!$G$7:$G$506,Pasivos!$B$7:$B$506,">="&H$6,Pasivos!$B$7:$B$506,"<"&EDATE(H$6,1),Pasivos!$C$7:$C$506,"Reclasificar a LP")) -> 0 | I23: =H23+SUMIFS(Pasivos!$G$7:$G$506,Pasivos!$B$7:$B$506,">="&I$6,Pasivos!$B$7:$B$506,"<"&EDATE(I$6,1),Pasivos!$C$7:$C$506,"Desembolso",Pasivos!$F$7:$F$506,"Corto plazo")-SUMIFS(Pasivos!$G$7:$G$506,Pasivos!$B$7:$B$506,">="&I$6,Pasivos!$B$7:$B$506,"<"&EDATE(I$6,1),Pasivos!$C$7:$C$506,"Amortización",Pasivos!$F$7:$F$506,"Corto plazo")+1*(SUMIFS(Pasivos!$G$7:$G$506,Pasivos!$B$7:$B$506,">="&I$6,Pasivos!$B$7:$B$506,"<"&EDATE(I$6,1),Pasivos!$C$7:$C$506,"Reclasificar a CP")-SUMIFS(Pasivos!$G$7:$G$506,Pasivos!$B$7:$B$506,">="&I$6,Pasivos!$B$7:$B$506,"<"&EDATE(I$6,1),Pasivos!$C$7:$C$506,"Reclasificar a LP")) -> 0 | J23: =I23+SUMIFS(Pasivos!$G$7:$G$506,Pasivos!$B$7:$B$506,">="&J$6,Pasivos!$B$7:$B$506,"<"&EDATE(J$6,1),Pasivos!$C$7:$C$506,"Desembolso",Pasivos!$F$7:$F$506,"Corto plazo")-SUMIFS(Pasivos!$G$7:$G$506,Pasivos!$B$7:$B$506,">="&J$6,Pasivos!$B$7:$B$506,"<"&EDATE(J$6,1),Pasivos!$C$7:$C$506,"Amortización",Pasivos!$F$7:$F$506,"Corto plazo")+1*(SUMIFS(Pasivos!$G$7:$G$506,Pasivos!$B$7:$B$506,">="&J$6,Pasivos!$B$7:$B$506,"<"&EDATE(J$6,1),Pasivos!$C$7:$C$506,"Reclasificar a CP")-SUMIFS(Pasivos!$G$7:$G$506,Pasivos!$B$7:$B$506,">="&J$6,Pasivos!$B$7:$B$506,"<"&EDATE(J$6,1),Pasivos!$C$7:$C$506,"Reclasificar a LP")) -> 0 | K23: =J23+SUMIFS(Pasivos!$G$7:$G$506,Pasivos!$B$7:$B$506,">="&K$6,Pasivos!$B$7:$B$506,"<"&EDATE(K$6,1),Pasivos!$C$7:$C$506,"Desembolso",Pasivos!$F$7:$F$506,"Corto plazo")-SUMIFS(Pasivos!$G$7:$G$506,Pasivos!$B$7:$B$506,">="&K$6,Pasivos!$B$7:$B$506,"<"&EDATE(K$6,1),Pasivos!$C$7:$C$506,"Amortización",Pasivos!$F$7:$F$506,"Corto plazo")+1*(SUMIFS(Pasivos!$G$7:$G$506,Pasivos!$B$7:$B$506,">="&K$6,Pasivos!$B$7:$B$506,"<"&EDATE(K$6,1),Pasivos!$C$7:$C$506,"Reclasificar a CP")-SUMIFS(Pasivos!$G$7:$G$506,Pasivos!$B$7:$B$506,">="&K$6,Pasivos!$B$7:$B$506,"<"&EDATE(K$6,1),Pasivos!$C$7:$C$506,"Reclasificar a LP")) -> 0 | ... N23: =M23+SUMIFS(Pasivos!$G$7:$G$506,Pasivos!$B$7:$B$506,">="&N$6,Pasivos!$B$7:$B$506,"<"&EDATE(N$6,1),Pasivos!$C$7:$C$506,"Desembolso",Pasivos!$F$7:$F$506,"Corto plazo")-SUMIFS(Pasivos!$G$7:$G$506,Pasivos!$B$7:$B$506,">="&N$6,Pasivos!$B$7:$B$506,"<"&EDATE(N$6,1),Pasivos!$C$7:$C$506,"Amortización",Pasivos!$F$7:$F$506,"Corto plazo")+1*(SUMIFS(Pasivos!$G$7:$G$506,Pasivos!$B$7:$B$506,">="&N$6,Pasivos!$B$7:$B$506,"<"&EDATE(N$6,1),Pasivos!$C$7:$C$506,"Reclasificar a CP")-SUMIFS(Pasivos!$G$7:$G$506,Pasivos!$B$7:$B$506,">="&N$6,Pasivos!$B$7:$B$506,"<"&EDATE(N$6,1),Pasivos!$C$7:$C$506,"Reclasificar a LP")) -> 0 | O23: =N23 -> 0
B24: Pasivo circulante | C24: =SUM(C19:C23) -> 0 | D24: =SUM(D19:D23) -> 0 | E24: =SUM(E19:E23) -> 0 | F24: =SUM(F19:F23) -> 0 | G24: =SUM(G19:G23) -> 0 | H24: =SUM(H19:H23) -> 0 | I24: =SUM(I19:I23) -> 0 | J24: =SUM(J19:J23) -> 0 | ... N24: =SUM(N19:N23) -> 0 | O24: =N24 -> 0
B25: Préstamos a largo plazo | C25: =SUMIFS(Pasivos!$G$7:$G$506,Pasivos!$C$7:$C$506,"Saldo inicial",Pasivos!$F$7:$F$506,"Largo plazo",Pasivos!$B$7:$B$506,DATE(Configuración!$C$5,1,1)-1)+SUMIFS(Pasivos!$G$7:$G$506,Pasivos!$B$7:$B$506,">="&C$6,Pasivos!$B$7:$B$506,"<"&EDATE(C$6,1),Pasivos!$C$7:$C$506,"Desembolso",Pasivos!$F$7:$F$506,"Largo plazo")-SUMIFS(Pasivos!$G$7:$G$506,Pasivos!$B$7:$B$506,">="&C$6,Pasivos!$B$7:$B$506,"<"&EDATE(C$6,1),Pasivos!$C$7:$C$506,"Amortización",Pasivos!$F$7:$F$506,"Largo plazo")+-1*(SUMIFS(Pasivos!$G$7:$G$506,Pasivos!$B$7:$B$506,">="&C$6,Pasivos!$B$7:$B$506,"<"&EDATE(C$6,1),Pasivos!$C$7:$C$506,"Reclasificar a CP")-SUMIFS(Pasivos!$G$7:$G$506,Pasivos!$B$7:$B$506,">="&C$6,Pasivos!$B$7:$B$506,"<"&EDATE(C$6,1),Pasivos!$C$7:$C$506,"Reclasificar a LP")) -> 0 | D25: =C25+SUMIFS(Pasivos!$G$7:$G$506,Pasivos!$B$7:$B$506,">="&D$6,Pasivos!$B$7:$B$506,"<"&EDATE(D$6,1),Pasivos!$C$7:$C$506,"Desembolso",Pasivos!$F$7:$F$506,"Largo plazo")-SUMIFS(Pasivos!$G$7:$G$506,Pasivos!$B$7:$B$506,">="&D$6,Pasivos!$B$7:$B$506,"<"&EDATE(D$6,1),Pasivos!$C$7:$C$506,"Amortización",Pasivos!$F$7:$F$506,"Largo plazo")+-1*(SUMIFS(Pasivos!$G$7:$G$506,Pasivos!$B$7:$B$506,">="&D$6,Pasivos!$B$7:$B$506,"<"&EDATE(D$6,1),Pasivos!$C$7:$C$506,"Reclasificar a CP")-SUMIFS(Pasivos!$G$7:$G$506,Pasivos!$B$7:$B$506,">="&D$6,Pasivos!$B$7:$B$506,"<"&EDATE(D$6,1),Pasivos!$C$7:$C$506,"Reclasificar a LP")) -> 0 | E25: =D25+SUMIFS(Pasivos!$G$7:$G$506,Pasivos!$B$7:$B$506,">="&E$6,Pasivos!$B$7:$B$506,"<"&EDATE(E$6,1),Pasivos!$C$7:$C$506,"Desembolso",Pasivos!$F$7:$F$506,"Largo plazo")-SUMIFS(Pasivos!$G$7:$G$506,Pasivos!$B$7:$B$506,">="&E$6,Pasivos!$B$7:$B$506,"<"&EDATE(E$6,1),Pasivos!$C$7:$C$506,"Amortización",Pasivos!$F$7:$F$506,"Largo plazo")+-1*(SUMIFS(Pasivos!$G$7:$G$506,Pasivos!$B$7:$B$506,">="&E$6,Pasivos!$B$7:$B$506,"<"&EDATE(E$6,1),Pasivos!$C$7:$C$506,"Reclasificar a CP")-SUMIFS(Pasivos!$G$7:$G$506,Pasivos!$B$7:$B$506,">="&E$6,Pasivos!$B$7:$B$506,"<"&EDATE(E$6,1),Pasivos!$C$7:$C$506,"Reclasificar a LP")) -> 0 | F25: =E25+SUMIFS(Pasivos!$G$7:$G$506,Pasivos!$B$7:$B$506,">="&F$6,Pasivos!$B$7:$B$506,"<"&EDATE(F$6,1),Pasivos!$C$7:$C$506,"Desembolso",Pasivos!$F$7:$F$506,"Largo plazo")-SUMIFS(Pasivos!$G$7:$G$506,Pasivos!$B$7:$B$506,">="&F$6,Pasivos!$B$7:$B$506,"<"&EDATE(F$6,1),Pasivos!$C$7:$C$506,"Amortización",Pasivos!$F$7:$F$506,"Largo plazo")+-1*(SUMIFS(Pasivos!$G$7:$G$506,Pasivos!$B$7:$B$506,">="&F$6,Pasivos!$B$7:$B$506,"<"&EDATE(F$6,1),Pasivos!$C$7:$C$506,"Reclasificar a CP")-SUMIFS(Pasivos!$G$7:$G$506,Pasivos!$B$7:$B$506,">="&F$6,Pasivos!$B$7:$B$506,"<"&EDATE(F$6,1),Pasivos!$C$7:$C$506,"Reclasificar a LP")) -> 0 | G25: =F25+SUMIFS(Pasivos!$G$7:$G$506,Pasivos!$B$7:$B$506,">="&G$6,Pasivos!$B$7:$B$506,"<"&EDATE(G$6,1),Pasivos!$C$7:$C$506,"Desembolso",Pasivos!$F$7:$F$506,"Largo plazo")-SUMIFS(Pasivos!$G$7:$G$506,Pasivos!$B$7:$B$506,">="&G$6,Pasivos!$B$7:$B$506,"<"&EDATE(G$6,1),Pasivos!$C$7:$C$506,"Amortización",Pasivos!$F$7:$F$506,"Largo plazo")+-1*(SUMIFS(Pasivos!$G$7:$G$506,Pasivos!$B$7:$B$506,">="&G$6,Pasivos!$B$7:$B$506,"<"&EDATE(G$6,1),Pasivos!$C$7:$C$506,"Reclasificar a CP")-SUMIFS(Pasivos!$G$7:$G$506,Pasivos!$B$7:$B$506,">="&G$6,Pasivos!$B$7:$B$506,"<"&EDATE(G$6,1),Pasivos!$C$7:$C$506,"Reclasificar a LP")) -> 0 | H25: =G25+SUMIFS(Pasivos!$G$7:$G$506,Pasivos!$B$7:$B$506,">="&H$6,Pasivos!$B$7:$B$506,"<"&EDATE(H$6,1),Pasivos!$C$7:$C$506,"Desembolso",Pasivos!$F$7:$F$506,"Largo plazo")-SUMIFS(Pasivos!$G$7:$G$506,Pasivos!$B$7:$B$506,">="&H$6,Pasivos!$B$7:$B$506,"<"&EDATE(H$6,1),Pasivos!$C$7:$C$506,"Amortización",Pasivos!$F$7:$F$506,"Largo plazo")+-1*(SUMIFS(Pasivos!$G$7:$G$506,Pasivos!$B$7:$B$506,">="&H$6,Pasivos!$B$7:$B$506,"<"&EDATE(H$6,1),Pasivos!$C$7:$C$506,"Reclasificar a CP")-SUMIFS(Pasivos!$G$7:$G$506,Pasivos!$B$7:$B$506,">="&H$6,Pasivos!$B$7:$B$506,"<"&EDATE(H$6,1),Pasivos!$C$7:$C$506,"Reclasificar a LP")) -> 0 | I25: =H25+SUMIFS(Pasivos!$G$7:$G$506,Pasivos!$B$7:$B$506,">="&I$6,Pasivos!$B$7:$B$506,"<"&EDATE(I$6,1),Pasivos!$C$7:$C$506,"Desembolso",Pasivos!$F$7:$F$506,"Largo plazo")-SUMIFS(Pasivos!$G$7:$G$506,Pasivos!$B$7:$B$506,">="&I$6,Pasivos!$B$7:$B$506,"<"&EDATE(I$6,1),Pasivos!$C$7:$C$506,"Amortización",Pasivos!$F$7:$F$506,"Largo plazo")+-1*(SUMIFS(Pasivos!$G$7:$G$506,Pasivos!$B$7:$B$506,">="&I$6,Pasivos!$B$7:$B$506,"<"&EDATE(I$6,1),Pasivos!$C$7:$C$506,"Reclasificar a CP")-SUMIFS(Pasivos!$G$7:$G$506,Pasivos!$B$7:$B$506,">="&I$6,Pasivos!$B$7:$B$506,"<"&EDATE(I$6,1),Pasivos!$C$7:$C$506,"Reclasificar a LP")) -> 0 | J25: =I25+SUMIFS(Pasivos!$G$7:$G$506,Pasivos!$B$7:$B$506,">="&J$6,Pasivos!$B$7:$B$506,"<"&EDATE(J$6,1),Pasivos!$C$7:$C$506,"Desembolso",Pasivos!$F$7:$F$506,"Largo plazo")-SUMIFS(Pasivos!$G$7:$G$506,Pasivos!$B$7:$B$506,">="&J$6,Pasivos!$B$7:$B$506,"<"&EDATE(J$6,1),Pasivos!$C$7:$C$506,"Amortización",Pasivos!$F$7:$F$506,"Largo plazo")+-1*(SUMIFS(Pasivos!$G$7:$G$506,Pasivos!$B$7:$B$506,">="&J$6,Pasivos!$B$7:$B$506,"<"&EDATE(J$6,1),Pasivos!$C$7:$C$506,"Reclasificar a CP")-SUMIFS(Pasivos!$G$7:$G$506,Pasivos!$B$7:$B$506,">="&J$6,Pasivos!$B$7:$B$506,"<"&EDATE(J$6,1),Pasivos!$C$7:$C$506,"Reclasificar a LP")) -> 0 | K25: =J25+SUMIFS(Pasivos!$G$7:$G$506,Pasivos!$B$7:$B$506,">="&K$6,Pasivos!$B$7:$B$506,"<"&EDATE(K$6,1),Pasivos!$C$7:$C$506,"Desembolso",Pasivos!$F$7:$F$506,"Largo plazo")-SUMIFS(Pasivos!$G$7:$G$506,Pasivos!$B$7:$B$506,">="&K$6,Pasivos!$B$7:$B$506,"<"&EDATE(K$6,1),Pasivos!$C$7:$C$506,"Amortización",Pasivos!$F$7:$F$506,"Largo plazo")+-1*(SUMIFS(Pasivos!$G$7:$G$506,Pasivos!$B$7:$B$506,">="&K$6,Pasivos!$B$7:$B$506,"<"&EDATE(K$6,1),Pasivos!$C$7:$C$506,"Reclasificar a CP")-SUMIFS(Pasivos!$G$7:$G$506,Pasivos!$B$7:$B$506,">="&K$6,Pasivos!$B$7:$B$506,"<"&EDATE(K$6,1),Pasivos!$C$7:$C$506,"Reclasificar a LP")) -> 0 | ... N25: =M25+SUMIFS(Pasivos!$G$7:$G$506,Pasivos!$B$7:$B$506,">="&N$6,Pasivos!$B$7:$B$506,"<"&EDATE(N$6,1),Pasivos!$C$7:$C$506,"Desembolso",Pasivos!$F$7:$F$506,"Largo plazo")-SUMIFS(Pasivos!$G$7:$G$506,Pasivos!$B$7:$B$506,">="&N$6,Pasivos!$B$7:$B$506,"<"&EDATE(N$6,1),Pasivos!$C$7:$C$506,"Amortización",Pasivos!$F$7:$F$506,"Largo plazo")+-1*(SUMIFS(Pasivos!$G$7:$G$506,Pasivos!$B$7:$B$506,">="&N$6,Pasivos!$B$7:$B$506,"<"&EDATE(N$6,1),Pasivos!$C$7:$C$506,"Reclasificar a CP")-SUMIFS(Pasivos!$G$7:$G$506,Pasivos!$B$7:$B$506,">="&N$6,Pasivos!$B$7:$B$506,"<"&EDATE(N$6,1),Pasivos!$C$7:$C$506,"Reclasificar a LP")) -> 0 | O25: =N25 -> 0
B26: Total pasivo | C26: =C24+C25 -> 0 | D26: =D24+D25 -> 0 | E26: =E24+E25 -> 0 | F26: =F24+F25 -> 0 | G26: =G24+G25 -> 0 | H26: =H24+H25 -> 0 | I26: =I24+I25 -> 0 | J26: =J24+J25 -> 0 | ... N26: =N24+N25 -> 0 | O26: =N26 -> 0
B28: Capital y aportaciones | C28: =Configuración!$C$18+'Flujo de Efectivo'!C19 -> 0 | D28: =C28+'Flujo de Efectivo'!D19 -> 0 | E28: =D28+'Flujo de Efectivo'!E19 -> 0 | F28: =E28+'Flujo de Efectivo'!F19 -> 0 | G28: =F28+'Flujo de Efectivo'!G19 -> 0 | H28: =G28+'Flujo de Efectivo'!H19 -> 0 | I28: =H28+'Flujo de Efectivo'!I19 -> 0 | J28: =I28+'Flujo de Efectivo'!J19 -> 0 | K28: =J28+'Flujo de Efectivo'!K19 -> 0 | ... N28: =M28+'Flujo de Efectivo'!N19 -> 0 | O28: =N28 -> 0
B29: Resultados acumulados | C29: =Configuración!$C$19 -> 0 | D29: =Configuración!$C$19 -> 0 | E29: =Configuración!$C$19 -> 0 | F29: =Configuración!$C$19 -> 0 | G29: =Configuración!$C$19 -> 0 | H29: =Configuración!$C$19 -> 0 | I29: =Configuración!$C$19 -> 0 | J29: =Configuración!$C$19 -> 0 | ... N29: =Configuración!$C$19 -> 0 | O29: =N29 -> 0
B30: Resultado del ejercicio acumulado | C30: =0+'Estado de Resultados'!C33 -> 2200 | D30: =C30+'Estado de Resultados'!D33 -> 2200 | E30: =D30+'Estado de Resultados'!E33 -> 2200 | F30: =E30+'Estado de Resultados'!F33 -> 2200 | G30: =F30+'Estado de Resultados'!G33 -> 2200 | H30: =G30+'Estado de Resultados'!H33 -> 2200 | I30: =H30+'Estado de Resultados'!I33 -> 2200 | J30: =I30+'Estado de Resultados'!J33 -> 2200 | K30: =J30+'Estado de Resultados'!K33 -> 2200 | ... N30: =M30+'Estado de Resultados'!N33 -> 2200 | O30: =N30 -> 2200
B31: Retiros acumulados (restan) | C31: =0+'Flujo de Efectivo'!C20 -> 0 | D31: =C31+'Flujo de Efectivo'!D20 -> 0 | E31: =D31+'Flujo de Efectivo'!E20 -> 0 | F31: =E31+'Flujo de Efectivo'!F20 -> 0 | G31: =F31+'Flujo de Efectivo'!G20 -> 0 | H31: =G31+'Flujo de Efectivo'!H20 -> 0 | I31: =H31+'Flujo de Efectivo'!I20 -> 0 | J31: =I31+'Flujo de Efectivo'!J20 -> 0 | K31: =J31+'Flujo de Efectivo'!K20 -> 0 | ... N31: =M31+'Flujo de Efectivo'!N20 -> 0 | O31: =N31 -> 0
B32: Patrimonio | C32: =SUM(C28:C30)-C31 -> 2200 | D32: =SUM(D28:D30)-D31 -> 2200 | E32: =SUM(E28:E30)-E31 -> 2200 | F32: =SUM(F28:F30)-F31 -> 2200 | G32: =SUM(G28:G30)-G31 -> 2200 | H32: =SUM(H28:H30)-H31 -> 2200 | I32: =SUM(I28:I30)-I31 -> 2200 | J32: =SUM(J28:J30)-J31 -> 2200 | ... N32: =SUM(N28:N30)-N31 -> 2200 | O32: =N32 -> 2200
